Workbook

Sheet Menu
A1: Agregador de dados para o Imposto de Renda
A2: ="Ano-calendário "&Parâmetros!B4&" | Declaração do exercício "&Parâmetros!B5 -> Ano-calendário 2026 | Declaração do exercício 2027
A3: Dados de exemplo (fictícios) nas abas. Apague antes de usar com suas informações.
A5: Seção | B5: O que registrar | C5: Itens | D5: Pendências
A6: Contribuinte | B6: Nome, CPF e nascimento | C6: =IF(Contribuinte!B5<>"",1,0) -> 1 | D6: =Resumo!B34 -> 0
A7: Dependentes | B7: Quem entra como dependente | C7: =COUNTA(Dependentes!A6:A15) -> 1 | D7: =Resumo!B35 -> 0
A8: Rendimentos | B8: Informes de rendimentos recebidos no ano | C8: =SUMPRODUCT(--(Rendimentos!K6:K105<>"")) -> 4 | D8: =Resumo!B36+Resumo!B37 -> 1
A9: Deduções | B9: Saúde, educação, previdência e pensão | C9: =SUMPRODUCT(--(Deduções!I6:I155<>"")) -> 4 | D9: =Resumo!B39+Resumo!B40 -> 1
A10: Bens e Direitos | B10: Patrimônio em 31/12 dos dois anos | C10: =SUMPRODUCT(--('Bens e Direitos'!G6:G65<>"")) -> 2 | D10: =COUNTIF('Bens e Direitos'!G6:G65,"Revisar") -> 0
A11: Dívidas | B11: Financiamentos e empréstimos | C11: =SUMPRODUCT(--(Dívidas!F6:F35<>"")) -> 1 | D11: =COUNTIF(Dívidas!F6:F35,"Revisar") -> 0
A12: Checklist | B12: Documentos que precisam estar em mãos | C12: =SUMPRODUCT(--(Checklist!E6:E25<>"")) -> 12 | D12: =Resumo!B44 -> 0
A13: Resumo | B13: Totais, base estimada e verificações | D13: =Resumo!B46 -> 2
A14: Parâmetros | B14: Ano-calendário e limites de referência
A15: Listas | B15: Opções dos menus suspensos
A17: Situação geral
A18: =IF(Resumo!B46=0,"Sem pendências. Confira os avisos no Resumo antes de transmitir.","Pendências a resolver: "&Resumo!B46&". Avisos para conferir: "&Resumo!B47&".") -> Pendências a resolver: 2. Avisos para conferir: 1.
A20: Links rápidos (abrem no navegador)
A21: Meu Imposto de Renda (Receita Federal)
A22: Portal da Receita Federal
A23: e-CAC: consultas e documentos fiscais
A25: Ferramenta de organização. Não calcula o imposto devido nem substitui o programa da Receita Federal.

Sheet Contribuinte
A1: ◄ Voltar ao Menu
A2: Contribuinte
A3: Dados de identificação. O CPF é conferido pelos dígitos verificadores.
A4: Campo | B4: Informação | C4: Conferência
A5: Nome completo | B5: Fulano de Tal (exemplo) | C5: =IF(B5="","Preencher","OK") -> OK
A6: CPF | B6: 111.444.777-35 | C6: =IF(B6="","Preencher",IF(IFERROR(AND(LEN(SUBSTITUTE(SUBSTITUTE(SUBSTITUTE(SUBSTITUTE(B6,".",""),"-","")," ",""),"/",""))=11,SUBSTITUTE(SUBSTITUTE(SUBSTITUTE(SUBSTITUTE(B6,".",""),"-","")," ",""),"/","")<>REPT(LEFT(SUBSTITUTE(SUBSTITUTE(SUBSTITUTE(SUBSTITUTE(B6,".",""),"-","")," ",""),"/",""),1),11),VALUE(MID(SUBSTITUTE(SUBSTITUTE(SUBSTITUTE(SUBSTITUTE(B6,".",""),"-","")," ",""),"/",""),10,1))=IF(MOD(SUMPRODUCT(--MID(SUBSTITUTE(SUBSTITUTE(SUBSTITUTE(SUBSTITUTE(B6,".",""),"-","")," ",""),"/",""),{1,2,3,4,5,6,7,8,9},1),{10,9,8,7,6,5,4,3,2}),11)<2,0,11-MOD(SUMPRODUCT(--MID(SUBSTITUTE(SUBSTITUTE(SUBSTITUTE(SUBSTITUTE(B6,".",""),"-","")," ",""),"/",""),{1,2,3,4,5,6,7,8,9},1),{10,9,8,7,6,5,4,3,2}),11)),VALUE(MID(SUBSTITUTE(SUBSTITUTE(SUBSTITUTE(SUBSTITUTE(B6,".",""),"-","")," ",""),"/",""),11,1))=IF(MOD(SUMPRODUCT(--MID(SUBSTITUTE(SUBSTITUTE(SUBSTITUTE(SUBSTITUTE(B6,".",""),"-","")," ",""),"/",""),{1,2,3,4,5,6,7,8,9,10},1),{11,10,9,8,7,6,5,4,3,2}),11)<2,0,11-MOD(SUMPRODUCT(--MID(SUBSTITUTE(SUBSTITUTE(SUBSTITUTE(SUBSTITUTE(B6,".",""),"-","")," ",""),"/",""),{1,2,3,4,5,6,7,8,9,10},1),{11,10,9,8,7,6,5,4,3,2}),11))),FALSE()),"CPF válido","CPF inválido")) -> CPF válido
A7: Data de nascimento | B7: 29351 | C7: =IF(B7="","Preencher","OK") -> OK
A8: Ocupação principal | B8: Analista
A9: Município e UF | B9: São Paulo/SP
A11: Dados de exemplo (fictícios). Apague antes de usar.

Sheet Dependentes
A1: ◄ Voltar ao Menu
A2: Dependentes
A3: Até 10 dependentes. Cada um gera a dedução anual definida em Parâmetros.
A5: Nome | B5: CPF | C5: Data de nascimento | D5: Parentesco | E5: CPF válido? | F5: Status
A6: Filho Exemplo | B6: 529.982.247-25 | C6: 40983 | D6: Filho(a) ou enteado(a) | E6: =IF(B6="","",IF(IFERROR(AND(LEN(SUBSTITUTE(SUBSTITUTE(SUBSTITUTE(SUBSTITUTE(B6,".",""),"-","")," ",""),"/",""))=11,SUBSTITUTE(SUBSTITUTE(SUBSTITUTE(SUBSTITUTE(B6,".",""),"-","")," ",""),"/","")<>REPT(LEFT(SUBSTITUTE(SUBSTITUTE(SUBSTITUTE(SUBSTITUTE(B6,".",""),"-","")," ",""),"/",""),1),11),VALUE(MID(SUBSTITUTE(SUBSTITUTE(SUBSTITUTE(SUBSTITUTE(B6,".",""),"-","")," ",""),"/",""),10,1))=IF(MOD(SUMPRODUCT(--MID(SUBSTITUTE(SUBSTITUTE(SUBSTITUTE(SUBSTITUTE(B6,".",""),"-","")," ",""),"/",""),{1,2,3,4,5,6,7,8,9},1),{10,9,8,7,6,5,4,3,2}),11)<2,0,11-MOD(SUMPRODUCT(--MID(SUBSTITUTE(SUBSTITUTE(SUBSTITUTE(SUBSTITUTE(B6,".",""),"-","")," ",""),"/",""),{1,2,3,4,5,6,7,8,9},1),{10,9,8,7,6,5,4,3,2}),11)),VALUE(MID(SUBSTITUTE(SUBSTITUTE(SUBSTITUTE(SUBSTITUTE(B6,".",""),"-","")," ",""),"/",""),11,1))=IF(MOD(SUMPRODUCT(--MID(SUBSTITUTE(SUBSTITUTE(SUBSTITUTE(SUBSTITUTE(B6,".",""),"-","")," ",""),"/",""),{1,2,3,4,5,6,7,8,9,10},1),{11,10,9,8,7,6,5,4,3,2}),11)<2,0,11-MOD(SUMPRODUCT(--MID(SUBSTITUTE(SUBSTITUTE(SUBSTITUTE(SUBSTITUTE(B6,".",""),"-","")," ",""),"/",""),{1,2,3,4,5,6,7,8,9,10},1),{11,10,9,8,7,6,5,4,3,2}),11))),FALSE()),"Sim","Não")) -> Sim | F6: =IF(A6="","",IF(OR(B6="",C6="",D6="",E6="Não"),"Revisar","OK")) -> OK
E7: =IF(B7="","",IF(IFERROR(AND(LEN(SUBSTITUTE(SUBSTITUTE(SUBSTITUTE(SUBSTITUTE(B7,".",""),"-","")," ",""),"/",""))=11,SUBSTITUTE(SUBSTITUTE(SUBSTITUTE(SUBSTITUTE(B7,".",""),"-","")," ",""),"/","")<>REPT(LEFT(SUBSTITUTE(SUBSTITUTE(SUBSTITUTE(SUBSTITUTE(B7,".",""),"-","")," ",""),"/",""),1),11),VALUE(MID(SUBSTITUTE(SUBSTITUTE(SUBSTITUTE(SUBSTITUTE(B7,".",""),"-","")," ",""),"/",""),10,1))=IF(MOD(SUMPRODUCT(--MID(SUBSTITUTE(SUBSTITUTE(SUBSTITUTE(SUBSTITUTE(B7,".",""),"-","")," ",""),"/",""),{1,2,3,4,5,6,7,8,9},1),{10,9,8,7,6,5,4,3,2}),11)<2,0,11-MOD(SUMPRODUCT(--MID(SUBSTITUTE(SUBSTITUTE(SUBSTITUTE(SUBSTITUTE(B7,".",""),"-","")," ",""),"/",""),{1,2,3,4,5,6,7,8,9},1),{10,9,8,7,6,5,4,3,2}),11)),VALUE(MID(SUBSTITUTE(SUBSTITUTE(SUBSTITUTE(SUBSTITUTE(B7,".",""),"-","")," ",""),"/",""),11,1))=IF(MOD(SUMPRODUCT(--MID(SUBSTITUTE(SUBSTITUTE(SUBSTITUTE(SUBSTITUTE(B7,".",""),"-","")," ",""),"/",""),{1,2,3,4,5,6,7,8,9,10},1),{11,10,9,8,7,6,5,4,3,2}),11)<2,0,11-MOD(SUMPRODUCT(--MID(SUBSTITUTE(SUBSTITUTE(SUBSTITUTE(SUBSTITUTE(B7,".",""),"-","")," ",""),"/",""),{1,2,3,4,5,6,7,8,9,10},1),{11,10,9,8,7,6,5,4,3,2}),11))),FALSE()),"Sim","Não")) | F7: =IF(A7="","",IF(OR(B7="",C7="",D7="",E7="Não"),"Revisar","OK"))
E8: =IF(B8="","",IF(IFERROR(AND(LEN(SUBSTITUTE(SUBSTITUTE(SUBSTITUTE(SUBSTITUTE(B8,".",""),"-","")," ",""),"/",""))=11,SUBSTITUTE(SUBSTITUTE(SUBSTITUTE(SUBSTITUTE(B8,".",""),"-","")," ",""),"/","")<>REPT(LEFT(SUBSTITUTE(SUBSTITUTE(SUBSTITUTE(SUBSTITUTE(B8,".",""),"-","")," ",""),"/",""),1),11),VALUE(MID(SUBSTITUTE(SUBSTITUTE(SUBSTITUTE(SUBSTITUTE(B8,".",""),"-","")," ",""),"/",""),10,1))=IF(MOD(SUMPRODUCT(--MID(SUBSTITUTE(SUBSTITUTE(SUBSTITUTE(SUBSTITUTE(B8,".",""),"-","")," ",""),"/",""),{1,2,3,4,5,6,7,8,9},1),{10,9,8,7,6,5,4,3,2}),11)<2,0,11-MOD(SUMPRODUCT(--MID(SUBSTITUTE(SUBSTITUTE(SUBSTITUTE(SUBSTITUTE(B8,".",""),"-","")," ",""),"/",""),{1,2,3,4,5,6,7,8,9},1),{10,9,8,7,6,5,4,3,2}),11)),VALUE(MID(SUBSTITUTE(SUBSTITUTE(SUBSTITUTE(SUBSTITUTE(B8,".",""),"-","")," ",""),"/",""),11,1))=IF(MOD(SUMPRODUCT(--MID(SUBSTITUTE(SUBSTITUTE(SUBSTITUTE(SUBSTITUTE(B8,".",""),"-","")," ",""),"/",""),{1,2,3,4,5,6,7,8,9,10},1),{11,10,9,8,7,6,5,4,3,2}),11)<2,0,11-MOD(SUMPRODUCT(--MID(SUBSTITUTE(SUBSTITUTE(SUBSTITUTE(SUBSTITUTE(B8,".",""),"-","")," ",""),"/",""),{1,2,3,4,5,6,7,8,9,10},1),{11,10,9,8,7,6,5,4,3,2}),11))),FALSE()),"Sim","Não")) | F8: =IF(A8="","",IF(OR(B8="",C8="",D8="",E8="Não"),"Revisar","OK"))
E9: =IF(B9="","",IF(IFERROR(AND(LEN(SUBSTITUTE(SUBSTITUTE(SUBSTITUTE(SUBSTITUTE(B9,".",""),"-","")," ",""),"/",""))=11,SUBSTITUTE(SUBSTITUTE(SUBSTITUTE(SUBSTITUTE(B9,".",""),"-","")," ",""),"/","")<>REPT(LEFT(SUBSTITUTE(SUBSTITUTE(SUBSTITUTE(SUBSTITUTE(B9,".",""),"-","")," ",""),"/",""),1),11),VALUE(MID(SUBSTITUTE(SUBSTITUTE(SUBSTITUTE(SUBSTITUTE(B9,".",""),"-","")," ",""),"/",""),10,1))=IF(MOD(SUMPRODUCT(--MID(SUBSTITUTE(SUBSTITUTE(SUBSTITUTE(SUBSTITUTE(B9,".",""),"-","")," ",""),"/",""),{1,2,3,4,5,6,7,8,9},1),{10,9,8,7,6,5,4,3,2}),11)<2,0,11-MOD(SUMPRODUCT(--MID(SUBSTITUTE(SUBSTITUTE(SUBSTITUTE(SUBSTITUTE(B9,".",""),"-","")," ",""),"/",""),{1,2,3,4,5,6,7,8,9},1),{10,9,8,7,6,5,4,3,2}),11)),VALUE(MID(SUBSTITUTE(SUBSTITUTE(SUBSTITUTE(SUBSTITUTE(B9,".",""),"-","")," ",""),"/",""),11,1))=IF(MOD(SUMPRODUCT(--MID(SUBSTITUTE(SUBSTITUTE(SUBSTITUTE(SUBSTITUTE(B9,".",""),"-","")," ",""),"/",""),{1,2,3,4,5,6,7,8,9,10},1),{11,10,9,8,7,6,5,4,3,2}),11)<2,0,11-MOD(SUMPRODUCT(--MID(SUBSTITUTE(SUBSTITUTE(SUBSTITUTE(SUBSTITUTE(B9,".",""),"-","")," ",""),"/",""),{1,2,3,4,5,6,7,8,9,10},1),{11,10,9,8,7,6,5,4,3,2}),11))),FALSE()),"Sim","Não")) | F9: =IF(A9="","",IF(OR(B9="",C9="",D9="",E9="Não"),"Revisar","OK"))
E10: =IF(B10="","",IF(IFERROR(AND(LEN(SUBSTITUTE(SUBSTITUTE(SUBSTITUTE(SUBSTITUTE(B10,".",""),"-","")," ",""),"/",""))=11,SUBSTITUTE(SUBSTITUTE(SUBSTITUTE(SUBSTITUTE(B10,".",""),"-","")," ",""),"/","")<>REPT(LEFT(SUBSTITUTE(SUBSTITUTE(SUBSTITUTE(SUBSTITUTE(B10,".",""),"-","")," ",""),"/",""),1),11),VALUE(MID(SUBSTITUTE(SUBSTITUTE(SUBSTITUTE(SUBSTITUTE(B10,".",""),"-","")," ",""),"/",""),10,1))=IF(MOD(SUMPRODUCT(--MID(SUBSTITUTE(SUBSTITUTE(SUBSTITUTE(SUBSTITUTE(B10,".",""),"-","")," ",""),"/",""),{1,2,3,4,5,6,7,8,9},1),{10,9,8,7,6,5,4,3,2}),11)<2,0,11-MOD(SUMPRODUCT(--MID(SUBSTITUTE(SUBSTITUTE(SUBSTITUTE(SUBSTITUTE(B10,".",""),"-","")," ",""),"/",""),{1,2,3,4,5,6,7,8,9},1),{10,9,8,7,6,5,4,3,2}),11)),VALUE(MID(SUBSTITUTE(SUBSTITUTE(SUBSTITUTE(SUBSTITUTE(B10,".",""),"-","")," ",""),"/",""),11,1))=IF(MOD(SUMPRODUCT(--MID(SUBSTITUTE(SUBSTITUTE(SUBSTITUTE(SUBSTITUTE(B10,".",""),"-","")," ",""),"/",""),{1,2,3,4,5,6,7,8,9,10},1),{11,10,9,8,7,6,5,4,3,2}),11)<2,0,11-MOD(SUMPRODUCT(--MID(SUBSTITUTE(SUBSTITUTE(SUBSTITUTE(SUBSTITUTE(B10,".",""),"-","")," ",""),"/",""),{1,2,3,4,5,6,7,8,9,10},1),{11,10,9,8,7,6,5,4,3,2}),11))),FALSE()),"Sim","Não")) | F10: =IF(A10="","",IF(OR(B10="",C10="",D10="",E10="Não"),"Revisar","OK"))
E11: =IF(B11="","",IF(IFERROR(AND(LEN(SUBSTITUTE(SUBSTITUTE(SUBSTITUTE(SUBSTITUTE(B11,".",""),"-","")," ",""),"/",""))=11,SUBSTITUTE(SUBSTITUTE(SUBSTITUTE(SUBSTITUTE(B11,".",""),"-","")," ",""),"/","")<>REPT(LEFT(SUBSTITUTE(SUBSTITUTE(SUBSTITUTE(SUBSTITUTE(B11,".",""),"-","")," ",""),"/",""),1),11),VALUE(MID(SUBSTITUTE(SUBSTITUTE(SUBSTITUTE(SUBSTITUTE(B11,".",""),"-","")," ",""),"/",""),10,1))=IF(MOD(SUMPRODUCT(--MID(SUBSTITUTE(SUBSTITUTE(SUBSTITUTE(SUBSTITUTE(B11,".",""),"-","")," ",""),"/",""),{1,2,3,4,5,6,7,8,9},1),{10,9,8,7,6,5,4,3,2}),11)<2,0,11-MOD(SUMPRODUCT(--MID(SUBSTITUTE(SUBSTITUTE(SUBSTITUTE(SUBSTITUTE(B11,".",""),"-","")," ",""),"/",""),{1,2,3,4,5,6,7,8,9},1),{10,9,8,7,6,5,4,3,2}),11)),VALUE(MID(SUBSTITUTE(SUBSTITUTE(SUBSTITUTE(SUBSTITUTE(B11,".",""),"-","")," ",""),"/",""),11,1))=IF(MOD(SUMPRODUCT(--MID(SUBSTITUTE(SUBSTITUTE(SUBSTITUTE(SUBSTITUTE(B11,".",""),"-","")," ",""),"/",""),{1,2,3,4,5,6,7,8,9,10},1),{11,10,9,8,7,6,5,4,3,2}),11)<2,0,11-MOD(SUMPRODUCT(--MID(SUBSTITUTE(SUBSTITUTE(SUBSTITUTE(SUBSTITUTE(B11,".",""),"-","")," ",""),"/",""),{1,2,3,4,5,6,7,8,9,10},1),{11,10,9,8,7,6,5,4,3,2}),11))),FALSE()),"Sim","Não")) | F11: =IF(A11="","",IF(OR(B11="",C11="",D11="",E11="Não"),"Revisar","OK"))
E12: =IF(B12="","",IF(IFERROR(AND(LEN(SUBSTITUTE(SUBSTITUTE(SUBSTITUTE(SUBSTITUTE(B12,".",""),"-","")," ",""),"/",""))=11,SUBSTITUTE(SUBSTITUTE(SUBSTITUTE(SUBSTITUTE(B12,".",""),"-","")," ",""),"/","")<>REPT(LEFT(SUBSTITUTE(SUBSTITUTE(SUBSTITUTE(SUBSTITUTE(B12,".",""),"-","")," ",""),"/",""),1),11),VALUE(MID(SUBSTITUTE(SUBSTITUTE(SUBSTITUTE(SUBSTITUTE(B12,".",""),"-","")," ",""),"/",""),10,1))=IF(MOD(SUMPRODUCT(--MID(SUBSTITUTE(SUBSTITUTE(SUBSTITUTE(SUBSTITUTE(B12,".",""),"-","")," ",""),"/",""),{1,2,3,4,5,6,7,8,9},1),{10,9,8,7,6,5,4,3,2}),11)<2,0,11-MOD(SUMPRODUCT(--MID(SUBSTITUTE(SUBSTITUTE(SUBSTITUTE(SUBSTITUTE(B12,".",""),"-","")," ",""),"/",""),{1,2,3,4,5,6,7,8,9},1),{10,9,8,7,6,5,4,3,2}),11)),VALUE(MID(SUBSTITUTE(SUBSTITUTE(SUBSTITUTE(SUBSTITUTE(B12,".",""),"-","")," ",""),"/",""),11,1))=IF(MOD(SUMPRODUCT(--MID(SUBSTITUTE(SUBSTITUTE(SUBSTITUTE(SUBSTITUTE(B12,".",""),"-","")," ",""),"/",""),{1,2,3,4,5,6,7,8,9,10},1),{11,10,9,8,7,6,5,4,3,2}),11)<2,0,11-MOD(SUMPRODUCT(--MID(SUBSTITUTE(SUBSTITUTE(SUBSTITUTE(SUBSTITUTE(B12,".",""),"-","")," ",""),"/",""),{1,2,3,4,5,6,7,8,9,10},1),{11,10,9,8,7,6,5,4,3,2}),11))),FALSE()),"Sim","Não")) | F12: =IF(A12="","",IF(OR(B12="",C12="",D12="",E12="Não"),"Revisar","OK"))
E13: =IF(B13="","",IF(IFERROR(AND(LEN(SUBSTITUTE(SUBSTITUTE(SUBSTITUTE(SUBSTITUTE(B13,".",""),"-","")," ",""),"/",""))=11,SUBSTITUTE(SUBSTITUTE(SUBSTITUTE(SUBSTITUTE(B13,".",""),"-","")," ",""),"/","")<>REPT(LEFT(SUBSTITUTE(SUBSTITUTE(SUBSTITUTE(SUBSTITUTE(B13,".",""),"-","")," ",""),"/",""),1),11),VALUE(MID(SUBSTITUTE(SUBSTITUTE(SUBSTITUTE(SUBSTITUTE(B13,".",""),"-","")," ",""),"/",""),10,1))=IF(MOD(SUMPRODUCT(--MID(SUBSTITUTE(SUBSTITUTE(SUBSTITUTE(SUBSTITUTE(B13,".",""),"-","")," ",""),"/",""),{1,2,3,4,5,6,7,8,9},1),{10,9,8,7,6,5,4,3,2}),11)<2,0,11-MOD(SUMPRODUCT(--MID(SUBSTITUTE(SUBSTITUTE(SUBSTITUTE(SUBSTITUTE(B13,".",""),"-","")," ",""),"/",""),{1,2,3,4,5,6,7,8,9},1),{10,9,8,7,6,5,4,3,2}),11)),VALUE(MID(SUBSTITUTE(SUBSTITUTE(SUBSTITUTE(SUBSTITUTE(B13,".",""),"-","")," ",""),"/",""),11,1))=IF(MOD(SUMPRODUCT(--MID(SUBSTITUTE(SUBSTITUTE(SUBSTITUTE(SUBSTITUTE(B13,".",""),"-","")," ",""),"/",""),{1,2,3,4,5,6,7,8,9,10},1),{11,10,9,8,7,6,5,4,3,2}),11)<2,0,11-MOD(SUMPRODUCT(--MID(SUBSTITUTE(SUBSTITUTE(SUBSTITUTE(SUBSTITUTE(B13,".",""),"-","")," ",""),"/",""),{1,2,3,4,5,6,7,8,9,10},1),{11,10,9,8,7,6,5,4,3,2}),11))),FALSE()),"Sim","Não")) | F13: =IF(A13="","",IF(OR(B13="",C13="",D13="",E13="Não"),"Revisar","OK"))
E14: =IF(B14="","",IF(IFERROR(AND(LEN(SUBSTITUTE(SUBSTITUTE(SUBSTITUTE(SUBSTITUTE(B14,".",""),"-","")," ",""),"/",""))=11,SUBSTITUTE(SUBSTITUTE(SUBSTITUTE(SUBSTITUTE(B14,".",""),"-","")," ",""),"/","")<>REPT(LEFT(SUBSTITUTE(SUBSTITUTE(SUBSTITUTE(SUBSTITUTE(B14,".",""),"-","")," ",""),"/",""),1),11),VALUE(MID(SUBSTITUTE(SUBSTITUTE(SUBSTITUTE(SUBSTITUTE(B14,".",""),"-","")," ",""),"/",""),10,1))=IF(MOD(SUMPRODUCT(--MID(SUBSTITUTE(SUBSTITUTE(SUBSTITUTE(SUBSTITUTE(B14,".",""),"-","")," ",""),"/",""),{1,2,3,4,5,6,7,8,9},1),{10,9,8,7,6,5,4,3,2}),11)<2,0,11-MOD(SUMPRODUCT(--MID(SUBSTITUTE(SUBSTITUTE(SUBSTITUTE(SUBSTITUTE(B14,".",""),"-","")," ",""),"/",""),{1,2,3,4,5,6,7,8,9},1),{10,9,8,7,6,5,4,3,2}),11)),VALUE(MID(SUBSTITUTE(SUBSTITUTE(SUBSTITUTE(SUBSTITUTE(B14,".",""),"-","")," ",""),"/",""),11,1))=IF(MOD(SUMPRODUCT(--MID(SUBSTITUTE(SUBSTITUTE(SUBSTITUTE(SUBSTITUTE(B14,".",""),"-","")," ",""),"/",""),{1,2,3,4,5,6,7,8,9,10},1),{11,10,9,8,7,6,5,4,3,2}),11)<2,0,11-MOD(SUMPRODUCT(--MID(SUBSTITUTE(SUBSTITUTE(SUBSTITUTE(SUBSTITUTE(B14,".",""),"-","")," ",""),"/",""),{1,2,3,4,5,6,7,8,9,10},1),{11,10,9,8,7,6,5,4,3,2}),11))),FALSE()),"Sim","Não")) | F14: =IF(A14="","",IF(OR(B14="",C14="",D14="",E14="Não"),"Revisar","OK"))
E15: =IF(B15="","",IF(IFERROR(AND(LEN(SUBSTITUTE(SUBSTITUTE(SUBSTITUTE(SUBSTITUTE(B15,".",""),"-","")," ",""),"/",""))=11,SUBSTITUTE(SUBSTITUTE(SUBSTITUTE(SUBSTITUTE(B15,".",""),"-","")," ",""),"/","")<>REPT(LEFT(SUBSTITUTE(SUBSTITUTE(SUBSTITUTE(SUBSTITUTE(B15,".",""),"-","")," ",""),"/",""),1),11),VALUE(MID(SUBSTITUTE(SUBSTITUTE(SUBSTITUTE(SUBSTITUTE(B15,".",""),"-","")," ",""),"/",""),10,1))=IF(MOD(SUMPRODUCT(--MID(SUBSTITUTE(SUBSTITUTE(SUBSTITUTE(SUBSTITUTE(B15,".",""),"-","")," ",""),"/",""),{1,2,3,4,5,6,7,8,9},1),{10,9,8,7,6,5,4,3,2}),11)<2,0,11-MOD(SUMPRODUCT(--MID(SUBSTITUTE(SUBSTITUTE(SUBSTITUTE(SUBSTITUTE(B15,".",""),"-","")," ",""),"/",""),{1,2,3,4,5,6,7,8,9},1),{10,9,8,7,6,5,4,3,2}),11)),VALUE(MID(SUBSTITUTE(SUBSTITUTE(SUBSTITUTE(SUBSTITUTE(B15,".",""),"-","")," ",""),"/",""),11,1))=IF(MOD(SUMPRODUCT(--MID(SUBSTITUTE(SUBSTITUTE(SUBSTITUTE(SUBSTITUTE(B15,".",""),"-","")," ",""),"/",""),{1,2,3,4,5,6,7,8,9,10},1),{11,10,9,8,7,6,5,4,3,2}),11)<2,0,11-MOD(SUMPRODUCT(--MID(SUBSTITUTE(SUBSTITUTE(SUBSTITUTE(SUBSTITUTE(B15,".",""),"-","")," ",""),"/",""),{1,2,3,4,5,6,7,8,9,10},1),{11,10,9,8,7,6,5,4,3,2}),11))),FALSE()),"Sim","Não")) | F15: =IF(A15="","",IF(OR(B15="",C15="",D15="",E15="Não"),"Revisar","OK"))

Sheet Rendimentos
A1: ◄ Voltar ao Menu
A2: Rendimentos
A3: Um lançamento por fonte pagadora e tipo (use os totais do informe de rendimentos). A classe é preenchida sozinha.
A5: Data de referência | B5: Fonte pagadora | C5: CNPJ ou CPF da fonte | D5: Tipo de rendimento | E5: Classe (automática) | F5: Valor bruto (R$) | G5: Imposto retido (R$) | H5: INSS retido (R$) | I5: Informe recebido? | J5: Observação | K5: Status
A6: 46387 | B6: Empresa Exemplo Ltda | C6: 12.345.678/0001-95 | D6: Salário ou pró-labore | E6: =IF(D6="","",IFERROR(VLOOKUP(D6,Listas!$A$5:$B$16,2,FALSE()),"")) -> Tributável | F6: 78000 | G6: 4800 | H6: 8556 | I6: Sim | K6: =IF(AND(A6="",B6="",D6="",F6=""),"",IF(OR(A6="",B6="",D6="",F6="",NOT(IFERROR(OR(IFERROR(AND(LEN(SUBSTITUTE(SUBSTITUTE(SUBSTITUTE(SUBSTITUTE(C6,".",""),"-","")," ",""),"/",""))=11,SUBSTITUTE(SUBSTITUTE(SUBSTITUTE(SUBSTITUTE(C6,".",""),"-","")," ",""),"/","")<>REPT(LEFT(SUBSTITUTE(SUBSTITUTE(SUBSTITUTE(SUBSTITUTE(C6,".",""),"-","")," ",""),"/",""),1),11),VALUE(MID(SUBSTITUTE(SUBSTITUTE(SUBSTITUTE(SUBSTITUTE(C6,".",""),"-","")," ",""),"/",""),10,1))=IF(MOD(SUMPRODUCT(--MID(SUBSTITUTE(SUBSTITUTE(SUBSTITUTE(SUBSTITUTE(C6,".",""),"-","")," ",""),"/",""),{1,2,3,4,5,6,7,8,9},1),{10,9,8,7,6,5,4,3,2}),11)<2,0,11-MOD(SUMPRODUCT(--MID(SUBSTITUTE(SUBSTITUTE(SUBSTITUTE(SUBSTITUTE(C6,".",""),"-","")," ",""),"/",""),{1,2,3,4,5,6,7,8,9},1),{10,9,8,7,6,5,4,3,2}),11)),VALUE(MID(SUBSTITUTE(SUBSTITUTE(SUBSTITUTE(SUBSTITUTE(C6,".",""),"-","")," ",""),"/",""),11,1))=IF(MOD(SUMPRODUCT(--MID(SUBSTITUTE(SUBSTITUTE(SUBSTITUTE(SUBSTITUTE(C6,".",""),"-","")," ",""),"/",""),{1,2,3,4,5,6,7,8,9,10},1),{11,10,9,8,7,6,5,4,3,2}),11)<2,0,11-MOD(SUMPRODUCT(--MID(SUBSTITUTE(SUBSTITUTE(SUBSTITUTE(SUBSTITUTE(C6,".",""),"-","")," ",""),"/",""),{1,2,3,4,5,6,7,8,9,10},1),{11,10,9,8,7,6,5,4,3,2}),11))),FALSE()),AND(LEN(SUBSTITUTE(SUBSTITUTE(SUBSTITUTE(SUBSTITUTE(C6,".",""),"-","")," ",""),"/",""))=14,ISNUMBER(VALUE(SUBSTITUTE(SUBSTITUTE(SUBSTITUTE(SUBSTITUTE(C6,".",""),"-","")," ",""),"/",""))))),FALSE())),G6>F6),"Revisar",IF(I6<>"Sim","Falta informe","OK"))) -> OK
A7: 46387 | B7: Empresa Exemplo Ltda | C7: 12.345.678/0001-95 | D7: 13º salário | E7: =IF(D7="","",IFERROR(VLOOKUP(D7,Listas!$A$5:$B$16,2,FALSE()),"")) -> Exclusivo na fonte | F7: 6500 | G7: 350 | H7: 0 | I7: Sim | K7: =IF(AND(A7="",B7="",D7="",F7=""),"",IF(OR(A7="",B7="",D7="",F7="",NOT(IFERROR(OR(IFERROR(AND(LEN(SUBSTITUTE(SUBSTITUTE(SUBSTITUTE(SUBSTITUTE(C7,".",""),"-","")," ",""),"/",""))=11,SUBSTITUTE(SUBSTITUTE(SUBSTITUTE(SUBSTITUTE(C7,".",""),"-","")," ",""),"/","")<>REPT(LEFT(SUBSTITUTE(SUBSTITUTE(SUBSTITUTE(SUBSTITUTE(C7,".",""),"-","")," ",""),"/",""),1),11),VALUE(MID(SUBSTITUTE(SUBSTITUTE(SUBSTITUTE(SUBSTITUTE(C7,".",""),"-","")," ",""),"/",""),10,1))=IF(MOD(SUMPRODUCT(--MID(SUBSTITUTE(SUBSTITUTE(SUBSTITUTE(SUBSTITUTE(C7,".",""),"-","")," ",""),"/",""),{1,2,3,4,5,6,7,8,9},1),{10,9,8,7,6,5,4,3,2}),11)<2,0,11-MOD(SUMPRODUCT(--MID(SUBSTITUTE(SUBSTITUTE(SUBSTITUTE(SUBSTITUTE(C7,".",""),"-","")," ",""),"/",""),{1,2,3,4,5,6,7,8,9},1),{10,9,8,7,6,5,4,3,2}),11)),VALUE(MID(SUBSTITUTE(SUBSTITUTE(SUBSTITUTE(SUBSTITUTE(C7,".",""),"-","")," ",""),"/",""),11,1))=IF(MOD(SUMPRODUCT(--MID(SUBSTITUTE(SUBSTITUTE(SUBSTITUTE(SUBSTITUTE(C7,".",""),"-","")," ",""),"/",""),{1,2,3,4,5,6,7,8,9,10},1),{11,10,9,8,7,6,5,4,3,2}),11)<2,0,11-MOD(SUMPRODUCT(--MID(SUBSTITUTE(SUBSTITUTE(SUBSTITUTE(SUBSTITUTE(C7,".",""),"-","")," ",""),"/",""),{1,2,3,4,5,6,7,8,9,10},1),{11,10,9,8,7,6,5,4,3,2}),11))),FALSE()),AND(LEN(SUBSTITUTE(SUBSTITUTE(SUBSTITUTE(SUBSTITUTE(C7,".",""),"-","")," ",""),"/",""))=14,ISNUMBER(VALUE(SUBSTITUTE(SUBSTITUTE(SUBSTITUTE(SUBSTITUTE(C7,".",""),"-","")," ",""),"/",""))))),FALSE())),G7>F7),"Revisar",IF(I7<>"Sim","Falta informe","OK"))) -> OK
A8: 46387 | B8: Banco Exemplo S.A. | C8: 98.765.432/0001-10 | D8: Rendimento de aplicação financeira | E8: =IF(D8="","",IFERROR(VLOOKUP(D8,Listas!$A$5:$B$16,2,FALSE()),"")) -> Exclusivo na fonte | F8: 1200 | G8: 180 | H8: 0 | I8: Sim | K8: =IF(AND(A8="",B8="",D8="",F8=""),"",IF(OR(A8="",B8="",D8="",F8="",NOT(IFERROR(OR(IFERROR(AND(LEN(SUBSTITUTE(SUBSTITUTE(SUBSTITUTE(SUBSTITUTE(C8,".",""),"-","")," ",""),"/",""))=11,SUBSTITUTE(SUBSTITUTE(SUBSTITUTE(SUBSTITUTE(C8,".",""),"-","")," ",""),"/","")<>REPT(LEFT(SUBSTITUTE(SUBSTITUTE(SUBSTITUTE(SUBSTITUTE(C8,".",""),"-","")," ",""),"/",""),1),11),VALUE(MID(SUBSTITUTE(SUBSTITUTE(SUBSTITUTE(SUBSTITUTE(C8,".",""),"-","")," ",""),"/",""),10,1))=IF(MOD(SUMPRODUCT(--MID(SUBSTITUTE(SUBSTITUTE(SUBSTITUTE(SUBSTITUTE(C8,".",""),"-","")," ",""),"/",""),{1,2,3,4,5,6,7,8,9},1),{10,9,8,7,6,5,4,3,2}),11)<2,0,11-MOD(SUMPRODUCT(--MID(SUBSTITUTE(SUBSTITUTE(SUBSTITUTE(SUBSTITUTE(C8,".",""),"-","")," ",""),"/",""),{1,2,3,4,5,6,7,8,9},1),{10,9,8,7,6,5,4,3,2}),11)),VALUE(MID(SUBSTITUTE(SUBSTITUTE(SUBSTITUTE(SUBSTITUTE(C8,".",""),"-","")," ",""),"/",""),11,1))=IF(MOD(SUMPRODUCT(--MID(SUBSTITUTE(SUBSTITUTE(SUBSTITUTE(SUBSTITUTE(C8,".",""),"-","")," ",""),"/",""),{1,2,3,4,5,6,7,8,9,10},1),{11,10,9,8,7,6,5,4,3,2}),11)<2,0,11-MOD(SUMPRODUCT(--MID(SUBSTITUTE(SUBSTITUTE(SUBSTITUTE(SUBSTITUTE(C8,".",""),"-","")," ",""),"/",""),{1,2,3,4,5,6,7,8,9,10},1),{11,10,9,8,7,6,5,4,3,2}),11))),FALSE()),AND(LEN(SUBSTITUTE(SUBSTITUTE(SUBSTITUTE(SUBSTITUTE(C8,".",""),"-","")," ",""),"/",""))=14,ISNUMBER(VALUE(SUBSTITUTE(SUBSTITUTE(SUBSTITUTE(SUBSTITUTE(C8,".",""),"-","")," ",""),"/",""))))),FALSE())),G8>F8),"Revisar",IF(I8<>"Sim","Falta informe","OK"))) -> OK
A9: 46387 | B9: Empresa Exemplo Ltda | C9: 12.345.678/0001-95 | D9: Verbas rescisórias indenizatórias e FGTS | E9: =IF(D9="","",IFERROR(VLOOKUP(D9,Listas!$A$5:$B$16,2,FALSE()),"")) -> Isento ou não tributável | F9: 12000 | G9: 0 | H9: 0 | I9: Não | K9: =IF(AND(A9="",B9="",D9="",F9=""),"",IF(OR(A9="",B9="",D9="",F9="",NOT(IFERROR(OR(IFERROR(AND(LEN(SUBSTITUTE(SUBSTITUTE(SUBSTITUTE(SUBSTITUTE(C9,".",""),"-","")," ",""),"/",""))=11,SUBSTITUTE(SUBSTITUTE(SUBSTITUTE(SUBSTITUTE(C9,".",""),"-","")," ",""),"/","")<>REPT(LEFT(SUBSTITUTE(SUBSTITUTE(SUBSTITUTE(SUBSTITUTE(C9,".",""),"-","")," ",""),"/",""),1),11),VALUE(MID(SUBSTITUTE(SUBSTITUTE(SUBSTITUTE(SUBSTITUTE(C9,".",""),"-","")," ",""),"/",""),10,1))=IF(MOD(SUMPRODUCT(--MID(SUBSTITUTE(SUBSTITUTE(SUBSTITUTE(SUBSTITUTE(C9,".",""),"-","")," ",""),"/",""),{1,2,3,4,5,6,7,8,9},1),{10,9,8,7,6,5,4,3,2}),11)<2,0,11-MOD(SUMPRODUCT(--MID(SUBSTITUTE(SUBSTITUTE(SUBSTITUTE(SUBSTITUTE(C9,".",""),"-","")," ",""),"/",""),{1,2,3,4,5,6,7,8,9},1),{10,9,8,7,6,5,4,3,2}),11)),VALUE(MID(SUBSTITUTE(SUBSTITUTE(SUBSTITUTE(SUBSTITUTE(C9,".",""),"-","")," ",""),"/",""),11,1))=IF(MOD(SUMPRODUCT(--MID(SUBSTITUTE(SUBSTITUTE(SUBSTITUTE(SUBSTITUTE(C9,".",""),"-","")," ",""),"/",""),{1,2,3,4,5,6,7,8,9,10},1),{11,10,9,8,7,6,5,4,3,2}),11)<2,0,11-MOD(SUMPRODUCT(--MID(SUBSTITUTE(SUBSTITUTE(SUBSTITUTE(SUBSTITUTE(C9,".",""),"-","")," ",""),"/",""),{1,2,3,4,5,6,7,8,9,10},1),{11,10,9,8,7,6,5,4,3,2}),11))),FALSE()),AND(LEN(SUBSTITUTE(SUBSTITUTE(SUBSTITUTE(SUBSTITUTE(C9,".",""),"-","")," ",""),"/",""))=14,ISNUMBER(VALUE(SUBSTITUTE(SUBSTITUTE(SUBSTITUTE(SUBSTITUTE(C9,".",""),"-","")," ",""),"/",""))))),FALSE())),G9>F9),"Revisar",IF(I9<>"Sim","Falta informe","OK"))) -> Falta informe
E10: =IF(D10="","",IFERROR(VLOOKUP(D10,Listas!$A$5:$B$16,2,FALSE()),"")) | K10: =IF(AND(A10="",B10="",D10="",F10=""),"",IF(OR(A10="",B10="",D10="",F10="",NOT(IFERROR(OR(IFERROR(AND(LEN(SUBSTITUTE(SUBSTITUTE(SUBSTITUTE(SUBSTITUTE(C10,".",""),"-","")," ",""),"/",""))=11,SUBSTITUTE(SUBSTITUTE(SUBSTITUTE(SUBSTITUTE(C10,".",""),"-","")," ",""),"/","")<>REPT(LEFT(SUBSTITUTE(SUBSTITUTE(SUBSTITUTE(SUBSTITUTE(C10,".",""),"-","")," ",""),"/",""),1),11),VALUE(MID(SUBSTITUTE(SUBSTITUTE(SUBSTITUTE(SUBSTITUTE(C10,".",""),"-","")," ",""),"/",""),10,1))=IF(MOD(SUMPRODUCT(--MID(SUBSTITUTE(SUBSTITUTE(SUBSTITUTE(SUBSTITUTE(C10,".",""),"-","")," ",""),"/",""),{1,2,3,4,5,6,7,8,9},1),{10,9,8,7,6,5,4,3,2}),11)<2,0,11-MOD(SUMPRODUCT(--MID(SUBSTITUTE(SUBSTITUTE(SUBSTITUTE(SUBSTITUTE(C10,".",""),"-","")," ",""),"/",""),{1,2,3,4,5,6,7,8,9},1),{10,9,8,7,6,5,4,3,2}),11)),VALUE(MID(SUBSTITUTE(SUBSTITUTE(SUBSTITUTE(SUBSTITUTE(C10,".",""),"-","")," ",""),"/",""),11,1))=IF(MOD(SUMPRODUCT(--MID(SUBSTITUTE(SUBSTITUTE(SUBSTITUTE(SUBSTITUTE(C10,".",""),"-","")," ",""),"/",""),{1,2,3,4,5,6,7,8,9,10},1),{11,10,9,8,7,6,5,4,3,2}),11)<2,0,11-MOD(SUMPRODUCT(--MID(SUBSTITUTE(SUBSTITUTE(SUBSTITUTE(SUBSTITUTE(C10,".",""),"-","")," ",""),"/",""),{1,2,3,4,5,6,7,8,9,10},1),{11,10,9,8,7,6,5,4,3,2}),11))),FALSE()),AND(LEN(SUBSTITUTE(SUBSTITUTE(SUBSTITUTE(SUBSTITUTE(C10,".",""),"-","")," ",""),"/",""))=14,ISNUMBER(VALUE(SUBSTITUTE(SUBSTITUTE(SUBSTITUTE(SUBSTITUTE(C10,".",""),"-","")," ",""),"/",""))))),FALSE())),G10>F10),"Revisar",IF(I10<>"Sim","Falta informe","OK")))
E11: =IF(D11="","",IFERROR(VLOOKUP(D11,Listas!$A$5:$B$16,2,FALSE()),"")) | K11: =IF(AND(A11="",B11="",D11="",F11=""),"",IF(OR(A11="",B11="",D11="",F11="",NOT(IFERROR(OR(IFERROR(AND(LEN(SUBSTITUTE(SUBSTITUTE(SUBSTITUTE(SUBSTITUTE(C11,".",""),"-","")," ",""),"/",""))=11,SUBSTITUTE(SUBSTITUTE(SUBSTITUTE(SUBSTITUTE(C11,".",""),"-","")," ",""),"/","")<>REPT(LEFT(SUBSTITUTE(SUBSTITUTE(SUBSTITUTE(SUBSTITUTE(C11,".",""),"-","")," ",""),"/",""),1),11),VALUE(MID(SUBSTITUTE(SUBSTITUTE(SUBSTITUTE(SUBSTITUTE(C11,".",""),"-","")," ",""),"/",""),10,1))=IF(MOD(SUMPRODUCT(--MID(SUBSTITUTE(SUBSTITUTE(SUBSTITUTE(SUBSTITUTE(C11,".",""),"-","")," ",""),"/",""),{1,2,3,4,5,6,7,8,9},1),{10,9,8,7,6,5,4,3,2}),11)<2,0,11-MOD(SUMPRODUCT(--MID(SUBSTITUTE(SUBSTITUTE(SUBSTITUTE(SUBSTITUTE(C11,".",""),"-","")," ",""),"/",""),{1,2,3,4,5,6,7,8,9},1),{10,9,8,7,6,5,4,3,2}),11)),VALUE(MID(SUBSTITUTE(SUBSTITUTE(SUBSTITUTE(SUBSTITUTE(C11,".",""),"-","")," ",""),"/",""),11,1))=IF(MOD(SUMPRODUCT(--MID(SUBSTITUTE(SUBSTITUTE(SUBSTITUTE(SUBSTITUTE(C11,".",""),"-","")," ",""),"/",""),{1,2,3,4,5,6,7,8,9,10},1),{11,10,9,8,7,6,5,4,3,2}),11)<2,0,11-MOD(SUMPRODUCT(--MID(SUBSTITUTE(SUBSTITUTE(SUBSTITUTE(SUBSTITUTE(C11,".",""),"-","")," ",""),"/",""),{1,2,3,4,5,6,7,8,9,10},1),{11,10,9,8,7,6,5,4,3,2}),11))),FALSE()),AND(LEN(SUBSTITUTE(SUBSTITUTE(SUBSTITUTE(SUBSTITUTE(C11,".",""),"-","")," ",""),"/",""))=14,ISNUMBER(VALUE(SUBSTITUTE(SUBSTITUTE(SUBSTITUTE(SUBSTITUTE(C11,".",""),"-","")," ",""),"/",""))))),FALSE())),G11>F11),"Revisar",IF(I11<>"Sim","Falta informe","OK")))
E12: =IF(D12="","",IFERROR(VLOOKUP(D12,Listas!$A$5:$B$16,2,FALSE()),"")) | K12: =IF(AND(A12="",B12="",D12="",F12=""),"",IF(OR(A12="",B12="",D12="",F12="",NOT(IFERROR(OR(IFERROR(AND(LEN(SUBSTITUTE(SUBSTITUTE(SUBSTITUTE(SUBSTITUTE(C12,".",""),"-","")," ",""),"/",""))=11,SUBSTITUTE(SUBSTITUTE(SUBSTITUTE(SUBSTITUTE(C12,".",""),"-","")," ",""),"/","")<>REPT(LEFT(SUBSTITUTE(SUBSTITUTE(SUBSTITUTE(SUBSTITUTE(C12,".",""),"-","")," ",""),"/",""),1),11),VALUE(MID(SUBSTITUTE(SUBSTITUTE(SUBSTITUTE(SUBSTITUTE(C12,".",""),"-","")," ",""),"/",""),10,1))=IF(MOD(SUMPRODUCT(--MID(SUBSTITUTE(SUBSTITUTE(SUBSTITUTE(SUBSTITUTE(C12,".",""),"-","")," ",""),"/",""),{1,2,3,4,5,6,7,8,9},1),{10,9,8,7,6,5,4,3,2}),11)<2,0,11-MOD(SUMPRODUCT(--MID(SUBSTITUTE(SUBSTITUTE(SUBSTITUTE(SUBSTITUTE(C12,".",""),"-","")," ",""),"/",""),{1,2,3,4,5,6,7,8,9},1),{10,9,8,7,6,5,4,3,2}),11)),VALUE(MID(SUBSTITUTE(SUBSTITUTE(SUBSTITUTE(SUBSTITUTE(C12,".",""),"-","")," ",""),"/",""),11,1))=IF(MOD(SUMPRODUCT(--MID(SUBSTITUTE(SUBSTITUTE(SUBSTITUTE(SUBSTITUTE(C12,".",""),"-","")," ",""),"/",""),{1,2,3,4,5,6,7,8,9,10},1),{11,10,9,8,7,6,5,4,3,2}),11)<2,0,11-MOD(SUMPRODUCT(--MID(SUBSTITUTE(SUBSTITUTE(SUBSTITUTE(SUBSTITUTE(C12,".",""),"-","")," ",""),"/",""),{1,2,3,4,5,6,7,8,9,10},1),{11,10,9,8,7,6,5,4,3,2}),11))),FALSE()),AND(LEN(SUBSTITUTE(SUBSTITUTE(SUBSTITUTE(SUBSTITUTE(C12,".",""),"-","")," ",""),"/",""))=14,ISNUMBER(VALUE(SUBSTITUTE(SUBSTITUTE(SUBSTITUTE(SUBSTITUTE(C12,".",""),"-","")," ",""),"/",""))))),FALSE())),G12>F12),"Revisar",IF(I12<>"Sim","Falta informe","OK")))
E13: =IF(D13="","",IFERROR(VLOOKUP(D13,Listas!$A$5:$B$16,2,FALSE()),"")) | K13: =IF(AND(A13="",B13="",D13="",F13=""),"",IF(OR(A13="",B13="",D13="",F13="",NOT(IFERROR(OR(IFERROR(AND(LEN(SUBSTITUTE(SUBSTITUTE(SUBSTITUTE(SUBSTITUTE(C13,".",""),"-","")," ",""),"/",""))=11,SUBSTITUTE(SUBSTITUTE(SUBSTITUTE(SUBSTITUTE(C13,".",""),"-","")," ",""),"/","")<>REPT(LEFT(SUBSTITUTE(SUBSTITUTE(SUBSTITUTE(SUBSTITUTE(C13,".",""),"-","")," ",""),"/",""),1),11),VALUE(MID(SUBSTITUTE(SUBSTITUTE(SUBSTITUTE(SUBSTITUTE(C13,".",""),"-","")," ",""),"/",""),10,1))=IF(MOD(SUMPRODUCT(--MID(SUBSTITUTE(SUBSTITUTE(SUBSTITUTE(SUBSTITUTE(C13,".",""),"-","")," ",""),"/",""),{1,2,3,4,5,6,7,8,9},1),{10,9,8,7,6,5,4,3,2}),11)<2,0,11-MOD(SUMPRODUCT(--MID(SUBSTITUTE(SUBSTITUTE(SUBSTITUTE(SUBSTITUTE(C13,".",""),"-","")," ",""),"/",""),{1,2,3,4,5,6,7,8,9},1),{10,9,8,7,6,5,4,3,2}),11)),VALUE(MID(SUBSTITUTE(SUBSTITUTE(SUBSTITUTE(SUBSTITUTE(C13,".",""),"-","")," ",""),"/",""),11,1))=IF(MOD(SUMPRODUCT(--MID(SUBSTITUTE(SUBSTITUTE(SUBSTITUTE(SUBSTITUTE(C13,".",""),"-","")," ",""),"/",""),{1,2,3,4,5,6,7,8,9,10},1),{11,10,9,8,7,6,5,4,3,2}),11)<2,0,11-MOD(SUMPRODUCT(--MID(SUBSTITUTE(SUBSTITUTE(SUBSTITUTE(SUBSTITUTE(C13,".",""),"-","")," ",""),"/",""),{1,2,3,4,5,6,7,8,9,10},1),{11,10,9,8,7,6,5,4,3,2}),11))),FALSE()),AND(LEN(SUBSTITUTE(SUBSTITUTE(SUBSTITUTE(SUBSTITUTE(C13,".",""),"-","")," ",""),"/",""))=14,ISNUMBER(VALUE(SUBSTITUTE(SUBSTITUTE(SUBSTITUTE(SUBSTITUTE(C13,".",""),"-","")," ",""),"/",""))))),FALSE())),G13>F13),"Revisar",IF(I13<>"Sim","Falta informe","OK")))
E14: =IF(D14="","",IFERROR(VLOOKUP(D14,Listas!$A$5:$B$16,2,FALSE()),"")) | K14: =IF(AND(A14="",B14="",D14="",F14=""),"",IF(OR(A14="",B14="",D14="",F14="",NOT(IFERROR(OR(IFERROR(AND(LEN(SUBSTITUTE(SUBSTITUTE(SUBSTITUTE(SUBSTITUTE(C14,".",""),"-","")," ",""),"/",""))=11,SUBSTITUTE(SUBSTITUTE(SUBSTITUTE(SUBSTITUTE(C14,".",""),"-","")," ",""),"/","")<>REPT(LEFT(SUBSTITUTE(SUBSTITUTE(SUBSTITUTE(SUBSTITUTE(C14,".",""),"-","")," ",""),"/",""),1),11),VALUE(MID(SUBSTITUTE(SUBSTITUTE(SUBSTITUTE(SUBSTITUTE(C14,".",""),"-","")," ",""),"/",""),10,1))=IF(MOD(SUMPRODUCT(--MID(SUBSTITUTE(SUBSTITUTE(SUBSTITUTE(SUBSTITUTE(C14,".",""),"-","")," ",""),"/",""),{1,2,3,4,5,6,7,8,9},1),{10,9,8,7,6,5,4,3,2}),11)<2,0,11-MOD(SUMPRODUCT(--MID(SUBSTITUTE(SUBSTITUTE(SUBSTITUTE(SUBSTITUTE(C14,".",""),"-","")," ",""),"/",""),{1,2,3,4,5,6,7,8,9},1),{10,9,8,7,6,5,4,3,2}),11)),VALUE(MID(SUBSTITUTE(SUBSTITUTE(SUBSTITUTE(SUBSTITUTE(C14,".",""),"-","")," ",""),"/",""),11,1))=IF(MOD(SUMPRODUCT(--MID(SUBSTITUTE(SUBSTITUTE(SUBSTITUTE(SUBSTITUTE(C14,".",""),"-","")," ",""),"/",""),{1,2,3,4,5,6,7,8,9,10},1),{11,10,9,8,7,6,5,4,3,2}),11)<2,0,11-MOD(SUMPRODUCT(--MID(SUBSTITUTE(SUBSTITUTE(SUBSTITUTE(SUBSTITUTE(C14,".",""),"-","")," ",""),"/",""),{1,2,3,4,5,6,7,8,9,10},1),{11,10,9,8,7,6,5,4,3,2}),11))),FALSE()),AND(LEN(SUBSTITUTE(SUBSTITUTE(SUBSTITUTE(SUBSTITUTE(C14,".",""),"-","")," ",""),"/",""))=14,ISNUMBER(VALUE(SUBSTITUTE(SUBSTITUTE(SUBSTITUTE(SUBSTITUTE(C14,".",""),"-","")," ",""),"/",""))))),FALSE())),G14>F14),"Revisar",IF(I14<>"Sim","Falta informe","OK")))
E15: =IF(D15="","",IFERROR(VLOOKUP(D15,Listas!$A$5:$B$16,2,FALSE()),"")) | K15: =IF(AND(A15="",B15="",D15="",F15=""),"",IF(OR(A15="",B15="",D15="",F15="",NOT(IFERROR(OR(IFERROR(AND(LEN(SUBSTITUTE(SUBSTITUTE(SUBSTITUTE(SUBSTITUTE(C15,".",""),"-","")," ",""),"/",""))=11,SUBSTITUTE(SUBSTITUTE(SUBSTITUTE(SUBSTITUTE(C15,".",""),"-","")," ",""),"/","")<>REPT(LEFT(SUBSTITUTE(SUBSTITUTE(SUBSTITUTE(SUBSTITUTE(C15,".",""),"-","")," ",""),"/",""),1),11),VALUE(MID(SUBSTITUTE(SUBSTITUTE(SUBSTITUTE(SUBSTITUTE(C15,".",""),"-","")," ",""),"/",""),10,1))=IF(MOD(SUMPRODUCT(--MID(SUBSTITUTE(SUBSTITUTE(SUBSTITUTE(SUBSTITUTE(C15,".",""),"-","")," ",""),"/",""),{1,2,3,4,5,6,7,8,9},1),{10,9,8,7,6,5,4,3,2}),11)<2,0,11-MOD(SUMPRODUCT(--MID(SUBSTITUTE(SUBSTITUTE(SUBSTITUTE(SUBSTITUTE(C15,".",""),"-","")," ",""),"/",""),{1,2,3,4,5,6,7,8,9},1),{10,9,8,7,6,5,4,3,2}),11)),VALUE(MID(SUBSTITUTE(SUBSTITUTE(SUBSTITUTE(SUBSTITUTE(C15,".",""),"-","")," ",""),"/",""),11,1))=IF(MOD(SUMPRODUCT(--MID(SUBSTITUTE(SUBSTITUTE(SUBSTITUTE(SUBSTITUTE(C15,".",""),"-","")," ",""),"/",""),{1,2,3,4,5,6,7,8,9,10},1),{11,10,9,8,7,6,5,4,3,2}),11)<2,0,11-MOD(SUMPRODUCT(--MID(SUBSTITUTE(SUBSTITUTE(SUBSTITUTE(SUBSTITUTE(C15,".",""),"-","")," ",""),"/",""),{1,2,3,4,5,6,7,8,9,10},1),{11,10,9,8,7,6,5,4,3,2}),11))),FALSE()),AND(LEN(SUBSTITUTE(SUBSTITUTE(SUBSTITUTE(SUBSTITUTE(C15,".",""),"-","")," ",""),"/",""))=14,ISNUMBER(VALUE(SUBSTITUTE(SUBSTITUTE(SUBSTITUTE(SUBSTITUTE(C15,".",""),"-","")," ",""),"/",""))))),FALSE())),G15>F15),"Revisar",IF(I15<>"Sim","Falta informe","OK")))
E16: =IF(D16="","",IFERROR(VLOOKUP(D16,Listas!$A$5:$B$16,2,FALSE()),"")) | K16: =IF(AND(A16="",B16="",D16="",F16=""),"",IF(OR(A16="",B16="",D16="",F16="",NOT(IFERROR(OR(IFERROR(AND(LEN(SUBSTITUTE(SUBSTITUTE(SUBSTITUTE(SUBSTITUTE(C16,".",""),"-","")," ",""),"/",""))=11,SUBSTITUTE(SUBSTITUTE(SUBSTITUTE(SUBSTITUTE(C16,".",""),"-","")," ",""),"/","")<>REPT(LEFT(SUBSTITUTE(SUBSTITUTE(SUBSTITUTE(SUBSTITUTE(C16,".",""),"-","")," ",""),"/",""),1),11),VALUE(MID(SUBSTITUTE(SUBSTITUTE(SUBSTITUTE(SUBSTITUTE(C16,".",""),"-","")," ",""),"/",""),10,1))=IF(MOD(SUMPRODUCT(--MID(SUBSTITUTE(SUBSTITUTE(SUBSTITUTE(SUBSTITUTE(C16,".",""),"-","")," ",""),"/",""),{1,2,3,4,5,6,7,8,9},1),{10,9,8,7,6,5,4,3,2}),11)<2,0,11-MOD(SUMPRODUCT(--MID(SUBSTITUTE(SUBSTITUTE(SUBSTITUTE(SUBSTITUTE(C16,".",""),"-","")," ",""),"/",""),{1,2,3,4,5,6,7,8,9},1),{10,9,8,7,6,5,4,3,2}),11)),VALUE(MID(SUBSTITUTE(SUBSTITUTE(SUBSTITUTE(SUBSTITUTE(C16,".",""),"-","")," ",""),"/",""),11,1))=IF(MOD(SUMPRODUCT(--MID(SUBSTITUTE(SUBSTITUTE(SUBSTITUTE(SUBSTITUTE(C16,".",""),"-","")," ",""),"/",""),{1,2,3,4,5,6,7,8,9,10},1),{11,10,9,8,7,6,5,4,3,2}),11)<2,0,11-MOD(SUMPRODUCT(--MID(SUBSTITUTE(SUBSTITUTE(SUBSTITUTE(SUBSTITUTE(C16,".",""),"-","")," ",""),"/",""),{1,2,3,4,5,6,7,8,9,10},1),{11,10,9,8,7,6,5,4,3,2}),11))),FALSE()),AND(LEN(SUBSTITUTE(SUBSTITUTE(SUBSTITUTE(SUBSTITUTE(C16,".",""),"-","")," ",""),"/",""))=14,ISNUMBER(VALUE(SUBSTITUTE(SUBSTITUTE(SUBSTITUTE(SUBSTITUTE(C16,".",""),"-","")," ",""),"/",""))))),FALSE())),G16>F16),"Revisar",IF(I16<>"Sim","Falta informe","OK")))
E17: =IF(D17="","",IFERROR(VLOOKUP(D17,Listas!$A$5:$B$16,2,FALSE()),"")) | K17: =IF(AND(A17="",B17="",D17="",F17=""),"",IF(OR(A17="",B17="",D17="",F17="",NOT(IFERROR(OR(IFERROR(AND(LEN(SUBSTITUTE(SUBSTITUTE(SUBSTITUTE(SUBSTITUTE(C17,".",""),"-","")," ",""),"/",""))=11,SUBSTITUTE(SUBSTITUTE(SUBSTITUTE(SUBSTITUTE(C17,".",""),"-","")," ",""),"/","")<>REPT(LEFT(SUBSTITUTE(SUBSTITUTE(SUBSTITUTE(SUBSTITUTE(C17,".",""),"-","")," ",""),"/",""),1),11),VALUE(MID(SUBSTITUTE(SUBSTITUTE(SUBSTITUTE(SUBSTITUTE(C17,".",""),"-","")," ",""),"/",""),10,1))=IF(MOD(SUMPRODUCT(--MID(SUBSTITUTE(SUBSTITUTE(SUBSTITUTE(SUBSTITUTE(C17,".",""),"-","")," ",""),"/",""),{1,2,3,4,5,6,7,8,9},1),{10,9,8,7,6,5,4,3,2}),11)<2,0,11-MOD(SUMPRODUCT(--MID(SUBSTITUTE(SUBSTITUTE(SUBSTITUTE(SUBSTITUTE(C17,".",""),"-","")," ",""),"/",""),{1,2,3,4,5,6,7,8,9},1),{10,9,8,7,6,5,4,3,2}),11)),VALUE(MID(SUBSTITUTE(SUBSTITUTE(SUBSTITUTE(SUBSTITUTE(C17,".",""),"-","")," ",""),"/",""),11,1))=IF(MOD(SUMPRODUCT(--MID(SUBSTITUTE(SUBSTITUTE(SUBSTITUTE(SUBSTITUTE(C17,".",""),"-","")," ",""),"/",""),{1,2,3,4,5,6,7,8,9,10},1),{11,10,9,8,7,6,5,4,3,2}),11)<2,0,11-MOD(SUMPRODUCT(--MID(SUBSTITUTE(SUBSTITUTE(SUBSTITUTE(SUBSTITUTE(C17,".",""),"-","")," ",""),"/",""),{1,2,3,4,5,6,7,8,9,10},1),{11,10,9,8,7,6,5,4,3,2}),11))),FALSE()),AND(LEN(SUBSTITUTE(SUBSTITUTE(SUBSTITUTE(SUBSTITUTE(C17,".",""),"-","")," ",""),"/",""))=14,ISNUMBER(VALUE(SUBSTITUTE(SUBSTITUTE(SUBSTITUTE(SUBSTITUTE(C17,".",""),"-","")," ",""),"/",""))))),FALSE())),G17>F17),"Revisar",IF(I17<>"Sim","Falta informe","OK")))
E18: =IF(D18="","",IFERROR(VLOOKUP(D18,Listas!$A$5:$B$16,2,FALSE()),"")) | K18: =IF(AND(A18="",B18="",D18="",F18=""),"",IF(OR(A18="",B18="",D18="",F18="",NOT(IFERROR(OR(IFERROR(AND(LEN(SUBSTITUTE(SUBSTITUTE(SUBSTITUTE(SUBSTITUTE(C18,".",""),"-","")," ",""),"/",""))=11,SUBSTITUTE(SUBSTITUTE(SUBSTITUTE(SUBSTITUTE(C18,".",""),"-","")," ",""),"/","")<>REPT(LEFT(SUBSTITUTE(SUBSTITUTE(SUBSTITUTE(SUBSTITUTE(C18,".",""),"-","")," ",""),"/",""),1),11),VALUE(MID(SUBSTITUTE(SUBSTITUTE(SUBSTITUTE(SUBSTITUTE(C18,".",""),"-","")," ",""),"/",""),10,1))=IF(MOD(SUMPRODUCT(--MID(SUBSTITUTE(SUBSTITUTE(SUBSTITUTE(SUBSTITUTE(C18,".",""),"-","")," ",""),"/",""),{1,2,3,4,5,6,7,8,9},1),{10,9,8,7,6,5,4,3,2}),11)<2,0,11-MOD(SUMPRODUCT(--MID(SUBSTITUTE(SUBSTITUTE(SUBSTITUTE(SUBSTITUTE(C18,".",""),"-","")," ",""),"/",""),{1,2,3,4,5,6,7,8,9},1),{10,9,8,7,6,5,4,3,2}),11)),VALUE(MID(SUBSTITUTE(SUBSTITUTE(SUBSTITUTE(SUBSTITUTE(C18,".",""),"-","")," ",""),"/",""),11,1))=IF(MOD(SUMPRODUCT(--MID(SUBSTITUTE(SUBSTITUTE(SUBSTITUTE(SUBSTITUTE(C18,".",""),"-","")," ",""),"/",""),{1,2,3,4,5,6,7,8,9,10},1),{11,10,9,8,7,6,5,4,3,2}),11)<2,0,11-MOD(SUMPRODUCT(--MID(SUBSTITUTE(SUBSTITUTE(SUBSTITUTE(SUBSTITUTE(C18,".",""),"-","")," ",""),"/",""),{1,2,3,4,5,6,7,8,9,10},1),{11,10,9,8,7,6,5,4,3,2}),11))),FALSE()),AND(LEN(SUBSTITUTE(SUBSTITUTE(SUBSTITUTE(SUBSTITUTE(C18,".",""),"-","")," ",""),"/",""))=14,ISNUMBER(VALUE(SUBSTITUTE(SUBSTITUTE(SUBSTITUTE(SUBSTITUTE(C18,".",""),"-","")," ",""),"/",""))))),FALSE())),G18>F18),"Revisar",IF(I18<>"Sim","Falta informe","OK")))
E19: =IF(D19="","",IFERROR(VLOOKUP(D19,Listas!$A$5:$B$16,2,FALSE()),"")) | K19: =IF(AND(A19="",B19="",D19="",F19=""),"",IF(OR(A19="",B19="",D19="",F19="",NOT(IFERROR(OR(IFERROR(AND(LEN(SUBSTITUTE(SUBSTITUTE(SUBSTITUTE(SUBSTITUTE(C19,".",""),"-","")," ",""),"/",""))=11,SUBSTITUTE(SUBSTITUTE(SUBSTITUTE(SUBSTITUTE(C19,".",""),"-","")," ",""),"/","")<>REPT(LEFT(SUBSTITUTE(SUBSTITUTE(SUBSTITUTE(SUBSTITUTE(C19,".",""),"-","")," ",""),"/",""),1),11),VALUE(MID(SUBSTITUTE(SUBSTITUTE(SUBSTITUTE(SUBSTITUTE(C19,".",""),"-","")," ",""),"/",""),10,1))=IF(MOD(SUMPRODUCT(--MID(SUBSTITUTE(SUBSTITUTE(SUBSTITUTE(SUBSTITUTE(C19,".",""),"-","")," ",""),"/",""),{1,2,3,4,5,6,7,8,9},1),{10,9,8,7,6,5,4,3,2}),11)<2,0,11-MOD(SUMPRODUCT(--MID(SUBSTITUTE(SUBSTITUTE(SUBSTITUTE(SUBSTITUTE(C19,".",""),"-","")," ",""),"/",""),{1,2,3,4,5,6,7,8,9},1),{10,9,8,7,6,5,4,3,2}),11)),VALUE(MID(SUBSTITUTE(SUBSTITUTE(SUBSTITUTE(SUBSTITUTE(C19,".",""),"-","")," ",""),"/",""),11,1))=IF(MOD(SUMPRODUCT(--MID(SUBSTITUTE(SUBSTITUTE(SUBSTITUTE(SUBSTITUTE(C19,".",""),"-","")," ",""),"/",""),{1,2,3,4,5,6,7,8,9,10},1),{11,10,9,8,7,6,5,4,3,2}),11)<2,0,11-MOD(SUMPRODUCT(--MID(SUBSTITUTE(SUBSTITUTE(SUBSTITUTE(SUBSTITUTE(C19,".",""),"-","")," ",""),"/",""),{1,2,3,4,5,6,7,8,9,10},1),{11,10,9,8,7,6,5,4,3,2}),11))),FALSE()),AND(LEN(SUBSTITUTE(SUBSTITUTE(SUBSTITUTE(SUBSTITUTE(C19,".",""),"-","")," ",""),"/",""))=14,ISNUMBER(VALUE(SUBSTITUTE(SUBSTITUTE(SUBSTITUTE(SUBSTITUTE(C19,".",""),"-","")," ",""),"/",""))))),FALSE())),G19>F19),"Revisar",IF(I19<>"Sim","Falta informe","OK")))
E20: =IF(D20="","",IFERROR(VLOOKUP(D20,Listas!$A$5:$B$16,2,FALSE()),"")) | K20: =IF(AND(A20="",B20="",D20="",F20=""),"",IF(OR(A20="",B20="",D20="",F20="",NOT(IFERROR(OR(IFERROR(AND(LEN(SUBSTITUTE(SUBSTITUTE(SUBSTITUTE(SUBSTITUTE(C20,".",""),"-","")," ",""),"/",""))=11,SUBSTITUTE(SUBSTITUTE(SUBSTITUTE(SUBSTITUTE(C20,".",""),"-","")," ",""),"/","")<>REPT(LEFT(SUBSTITUTE(SUBSTITUTE(SUBSTITUTE(SUBSTITUTE(C20,".",""),"-","")," ",""),"/",""),1),11),VALUE(MID(SUBSTITUTE(SUBSTITUTE(SUBSTITUTE(SUBSTITUTE(C20,".",""),"-","")," ",""),"/",""),10,1))=IF(MOD(SUMPRODUCT(--MID(SUBSTITUTE(SUBSTITUTE(SUBSTITUTE(SUBSTITUTE(C20,".",""),"-","")," ",""),"/",""),{1,2,3,4,5,6,7,8,9},1),{10,9,8,7,6,5,4,3,2}),11)<2,0,11-MOD(SUMPRODUCT(--MID(SUBSTITUTE(SUBSTITUTE(SUBSTITUTE(SUBSTITUTE(C20,".",""),"-","")," ",""),"/",""),{1,2,3,4,5,6,7,8,9},1),{10,9,8,7,6,5,4,3,2}),11)),VALUE(MID(SUBSTITUTE(SUBSTITUTE(SUBSTITUTE(SUBSTITUTE(C20,".",""),"-","")," ",""),"/",""),11,1))=IF(MOD(SUMPRODUCT(--MID(SUBSTITUTE(SUBSTITUTE(SUBSTITUTE(SUBSTITUTE(C20,".",""),"-","")," ",""),"/",""),{1,2,3,4,5,6,7,8,9,10},1),{11,10,9,8,7,6,5,4,3,2}),11)<2,0,11-MOD(SUMPRODUCT(--MID(SUBSTITUTE(SUBSTITUTE(SUBSTITUTE(SUBSTITUTE(C20,".",""),"-","")," ",""),"/",""),{1,2,3,4,5,6,7,8,9,10},1),{11,10,9,8,7,6,5,4,3,2}),11))),FALSE()),AND(LEN(SUBSTITUTE(SUBSTITUTE(SUBSTITUTE(SUBSTITUTE(C20,".",""),"-","")," ",""),"/",""))=14,ISNUMBER(VALUE(SUBSTITUTE(SUBSTITUTE(SUBSTITUTE(SUBSTITUTE(C20,".",""),"-","")," ",""),"/",""))))),FALSE())),G20>F20),"Revisar",IF(I20<>"Sim","Falta informe","OK")))
E21: =IF(D21="","",IFERROR(VLOOKUP(D21,Listas!$A$5:$B$16,2,FALSE()),"")) | K21: =IF(AND(A21="",B21="",D21="",F21=""),"",IF(OR(A21="",B21="",D21="",F21="",NOT(IFERROR(OR(IFERROR(AND(LEN(SUBSTITUTE(SUBSTITUTE(SUBSTITUTE(SUBSTITUTE(C21,".",""),"-","")," ",""),"/",""))=11,SUBSTITUTE(SUBSTITUTE(SUBSTITUTE(SUBSTITUTE(C21,".",""),"-","")," ",""),"/","")<>REPT(LEFT(SUBSTITUTE(SUBSTITUTE(SUBSTITUTE(SUBSTITUTE(C21,".",""),"-","")," ",""),"/",""),1),11),VALUE(MID(SUBSTITUTE(SUBSTITUTE(SUBSTITUTE(SUBSTITUTE(C21,".",""),"-","")," ",""),"/",""),10,1))=IF(MOD(SUMPRODUCT(--MID(SUBSTITUTE(SUBSTITUTE(SUBSTITUTE(SUBSTITUTE(C21,".",""),"-","")," ",""),"/",""),{1,2,3,4,5,6,7,8,9},1),{10,9,8,7,6,5,4,3,2}),11)<2,0,11-MOD(SUMPRODUCT(--MID(SUBSTITUTE(SUBSTITUTE(SUBSTITUTE(SUBSTITUTE(C21,".",""),"-","")," ",""),"/",""),{1,2,3,4,5,6,7,8,9},1),{10,9,8,7,6,5,4,3,2}),11)),VALUE(MID(SUBSTITUTE(SUBSTITUTE(SUBSTITUTE(SUBSTITUTE(C21,".",""),"-","")," ",""),"/",""),11,1))=IF(MOD(SUMPRODUCT(--MID(SUBSTITUTE(SUBSTITUTE(SUBSTITUTE(SUBSTITUTE(C21,".",""),"-","")," ",""),"/",""),{1,2,3,4,5,6,7,8,9,10},1),{11,10,9,8,7,6,5,4,3,2}),11)<2,0,11-MOD(SUMPRODUCT(--MID(SUBSTITUTE(SUBSTITUTE(SUBSTITUTE(SUBSTITUTE(C21,".",""),"-","")," ",""),"/",""),{1,2,3,4,5,6,7,8,9,10},1),{11,10,9,8,7,6,5,4,3,2}),11))),FALSE()),AND(LEN(SUBSTITUTE(SUBSTITUTE(SUBSTITUTE(SUBSTITUTE(C21,".",""),"-","")," ",""),"/",""))=14,ISNUMBER(VALUE(SUBSTITUTE(SUBSTITUTE(SUBSTITUTE(SUBSTITUTE(C21,".",""),"-","")," ",""),"/",""))))),FALSE())),G21>F21),"Revisar",IF(I21<>"Sim","Falta informe","OK")))
... E105: =IF(D105="","",IFERROR(VLOOKUP(D105,Listas!$A$5:$B$16,2,FALSE()),"")) | K105: =IF(AND(A105="",B105="",D105="",F105=""),"",IF(OR(A105="",B105="",D105="",F105="",NOT(IFERROR(OR(IFERROR(AND(LEN(SUBSTITUTE(SUBSTITUTE(SUBSTITUTE(SUBSTITUTE(C105,".",""),"-","")," ",""),"/",""))=11,SUBSTITUTE(SUBSTITUTE(SUBSTITUTE(SUBSTITUTE(C105,".",""),"-","")," ",""),"/","")<>REPT(LEFT(SUBSTITUTE(SUBSTITUTE(SUBSTITUTE(SUBSTITUTE(C105,".",""),"-","")," ",""),"/",""),1),11),VALUE(MID(SUBSTITUTE(SUBSTITUTE(SUBSTITUTE(SUBSTITUTE(C105,".",""),"-","")," ",""),"/",""),10,1))=IF(MOD(SUMPRODUCT(--MID(SUBSTITUTE(SUBSTITUTE(SUBSTITUTE(SUBSTITUTE(C105,".",""),"-","")," ",""),"/",""),{1,2,3,4,5,6,7,8,9},1),{10,9,8,7,6,5,4,3,2}),11)<2,0,11-MOD(SUMPRODUCT(--MID(SUBSTITUTE(SUBSTITUTE(SUBSTITUTE(SUBSTITUTE(C105,".",""),"-","")," ",""),"/",""),{1,2,3,4,5,6,7,8,9},1),{10,9,8,7,6,5,4,3,2}),11)),VALUE(MID(SUBSTITUTE(SUBSTITUTE(SUBSTITUTE(SUBSTITUTE(C105,".",""),"-","")," ",""),"/",""),11,1))=IF(MOD(SUMPRODUCT(--MID(SUBSTITUTE(SUBSTITUTE(SUBSTITUTE(SUBSTITUTE(C105,".",""),"-","")," ",""),"/",""),{1,2,3,4,5,6,7,8,9,10},1),{11,10,9,8,7,6,5,4,3,2}),11)<2,0,11-MOD(SUMPRODUCT(--MID(SUBSTITUTE(SUBSTITUTE(SUBSTITUTE(SUBSTITUTE(C105,".",""),"-","")," ",""),"/",""),{1,2,3,4,5,6,7,8,9,10},1),{11,10,9,8,7,6,5,4,3,2}),11))),FALSE()),AND(LEN(SUBSTITUTE(SUBSTITUTE(SUBSTITUTE(SUBSTITUTE(C105,".",""),"-","")," ",""),"/",""))=14,ISNUMBER(VALUE(SUBSTITUTE(SUBSTITUTE(SUBSTITUTE(SUBSTITUTE(C105,".",""),"-","")," ",""),"/",""))))),FALSE())),G105>F105),"Revisar",IF(I105<>"Sim","Falta informe","OK")))

Sheet Deduções
A1: ◄ Voltar ao Menu
A2: Deduções
A3: Um lançamento por comprovante ou grupo de comprovantes. Educação tem limite por pessoa, saúde não tem limite.
A5: Data | B5: Tipo de dedução | C5: Beneficiário | D5: Prestador ou descrição | E5: CNPJ ou CPF do prestador | F5: Valor (R$) | G5: Comprovante guardado? | H5: Observação | I5: Status
A6: 46091 | B6: Saúde | C6: Fulano de Tal (exemplo) | D6: Clínica Exemplo | E6: 23.456.789/0001-01 | F6: 2400 | G6: Sim | I6: =IF(AND(B6="",F6=""),"",IF(OR(A6="",B6="",C6="",F6="",NOT(IFERROR(OR(IFERROR(AND(LEN(SUBSTITUTE(SUBSTITUTE(SUBSTITUTE(SUBSTITUTE(E6,".",""),"-","")," ",""),"/",""))=11,SUBSTITUTE(SUBSTITUTE(SUBSTITUTE(SUBSTITUTE(E6,".",""),"-","")," ",""),"/","")<>REPT(LEFT(SUBSTITUTE(SUBSTITUTE(SUBSTITUTE(SUBSTITUTE(E6,".",""),"-","")," ",""),"/",""),1),11),VALUE(MID(SUBSTITUTE(SUBSTITUTE(SUBSTITUTE(SUBSTITUTE(E6,".",""),"-","")," ",""),"/",""),10,1))=IF(MOD(SUMPRODUCT(--MID(SUBSTITUTE(SUBSTITUTE(SUBSTITUTE(SUBSTITUTE(E6,".",""),"-","")," ",""),"/",""),{1,2,3,4,5,6,7,8,9},1),{10,9,8,7,6,5,4,3,2}),11)<2,0,11-MOD(SUMPRODUCT(--MID(SUBSTITUTE(SUBSTITUTE(SUBSTITUTE(SUBSTITUTE(E6,".",""),"-","")," ",""),"/",""),{1,2,3,4,5,6,7,8,9},1),{10,9,8,7,6,5,4,3,2}),11)),VALUE(MID(SUBSTITUTE(SUBSTITUTE(SUBSTITUTE(SUBSTITUTE(E6,".",""),"-","")," ",""),"/",""),11,1))=IF(MOD(SUMPRODUCT(--MID(SUBSTITUTE(SUBSTITUTE(SUBSTITUTE(SUBSTITUTE(E6,".",""),"-","")," ",""),"/",""),{1,2,3,4,5,6,7,8,9,10},1),{11,10,9,8,7,6,5,4,3,2}),11)<2,0,11-MOD(SUMPRODUCT(--MID(SUBSTITUTE(SUBSTITUTE(SUBSTITUTE(SUBSTITUTE(E6,".",""),"-","")," ",""),"/",""),{1,2,3,4,5,6,7,8,9,10},1),{11,10,9,8,7,6,5,4,3,2}),11))),FALSE()),AND(LEN(SUBSTITUTE(SUBSTITUTE(SUBSTITUTE(SUBSTITUTE(E6,".",""),"-","")," ",""),"/",""))=14,ISNUMBER(VALUE(SUBSTITUTE(SUBSTITUTE(SUBSTITUTE(SUBSTITUTE(E6,".",""),"-","")," ",""),"/",""))))),FALSE()))),"Revisar",IF(G6<>"Sim","Falta comprovante",IF(AND(B6="Educação",SUMIFS($F$6:$F$155,$B$6:$B$155,"Educação",$C$6:$C$155,C6)>Parâmetros!$B$6),"Acima do limite","OK")))) -> OK
A7: 46178 | B7: Saúde | C7: Filho Exemplo | D7: Dentista Exemplo | E7: 529.982.247-25 | F7: 800 | G7: Sim | I7: =IF(AND(B7="",F7=""),"",IF(OR(A7="",B7="",C7="",F7="",NOT(IFERROR(OR(IFERROR(AND(LEN(SUBSTITUTE(SUBSTITUTE(SUBSTITUTE(SUBSTITUTE(E7,".",""),"-","")," ",""),"/",""))=11,SUBSTITUTE(SUBSTITUTE(SUBSTITUTE(SUBSTITUTE(E7,".",""),"-","")," ",""),"/","")<>REPT(LEFT(SUBSTITUTE(SUBSTITUTE(SUBSTITUTE(SUBSTITUTE(E7,".",""),"-","")," ",""),"/",""),1),11),VALUE(MID(SUBSTITUTE(SUBSTITUTE(SUBSTITUTE(SUBSTITUTE(E7,".",""),"-","")," ",""),"/",""),10,1))=IF(MOD(SUMPRODUCT(--MID(SUBSTITUTE(SUBSTITUTE(SUBSTITUTE(SUBSTITUTE(E7,".",""),"-","")," ",""),"/",""),{1,2,3,4,5,6,7,8,9},1),{10,9,8,7,6,5,4,3,2}),11)<2,0,11-MOD(SUMPRODUCT(--MID(SUBSTITUTE(SUBSTITUTE(SUBSTITUTE(SUBSTITUTE(E7,".",""),"-","")," ",""),"/",""),{1,2,3,4,5,6,7,8,9},1),{10,9,8,7,6,5,4,3,2}),11)),VALUE(MID(SUBSTITUTE(SUBSTITUTE(SUBSTITUTE(SUBSTITUTE(E7,".",""),"-","")," ",""),"/",""),11,1))=IF(MOD(SUMPRODUCT(--MID(SUBSTITUTE(SUBSTITUTE(SUBSTITUTE(SUBSTITUTE(E7,".",""),"-","")," ",""),"/",""),{1,2,3,4,5,6,7,8,9,10},1),{11,10,9,8,7,6,5,4,3,2}),11)<2,0,11-MOD(SUMPRODUCT(--MID(SUBSTITUTE(SUBSTITUTE(SUBSTITUTE(SUBSTITUTE(E7,".",""),"-","")," ",""),"/",""),{1,2,3,4,5,6,7,8,9,10},1),{11,10,9,8,7,6,5,4,3,2}),11))),FALSE()),AND(LEN(SUBSTITUTE(SUBSTITUTE(SUBSTITUTE(SUBSTITUTE(E7,".",""),"-","")," ",""),"/",""))=14,ISNUMBER(VALUE(SUBSTITUTE(SUBSTITUTE(SUBSTITUTE(SUBSTITUTE(E7,".",""),"-","")," ",""),"/",""))))),FALSE()))),"Revisar",IF(G7<>"Sim","Falta comprovante",IF(AND(B7="Educação",SUMIFS($F$6:$F$155,$B$6:$B$155,"Educação",$C$6:$C$155,C7)>Parâmetros!$B$6),"Acima do limite","OK")))) -> OK
A8: 46387 | B8: Educação | C8: Filho Exemplo | D8: Escola Exemplo | E8: 34.567.890/0001-12 | F8: 5200 | G8: Sim | I8: =IF(AND(B8="",F8=""),"",IF(OR(A8="",B8="",C8="",F8="",NOT(IFERROR(OR(IFERROR(AND(LEN(SUBSTITUTE(SUBSTITUTE(SUBSTITUTE(SUBSTITUTE(E8,".",""),"-","")," ",""),"/",""))=11,SUBSTITUTE(SUBSTITUTE(SUBSTITUTE(SUBSTITUTE(E8,".",""),"-","")," ",""),"/","")<>REPT(LEFT(SUBSTITUTE(SUBSTITUTE(SUBSTITUTE(SUBSTITUTE(E8,".",""),"-","")," ",""),"/",""),1),11),VALUE(MID(SUBSTITUTE(SUBSTITUTE(SUBSTITUTE(SUBSTITUTE(E8,".",""),"-","")," ",""),"/",""),10,1))=IF(MOD(SUMPRODUCT(--MID(SUBSTITUTE(SUBSTITUTE(SUBSTITUTE(SUBSTITUTE(E8,".",""),"-","")," ",""),"/",""),{1,2,3,4,5,6,7,8,9},1),{10,9,8,7,6,5,4,3,2}),11)<2,0,11-MOD(SUMPRODUCT(--MID(SUBSTITUTE(SUBSTITUTE(SUBSTITUTE(SUBSTITUTE(E8,".",""),"-","")," ",""),"/",""),{1,2,3,4,5,6,7,8,9},1),{10,9,8,7,6,5,4,3,2}),11)),VALUE(MID(SUBSTITUTE(SUBSTITUTE(SUBSTITUTE(SUBSTITUTE(E8,".",""),"-","")," ",""),"/",""),11,1))=IF(MOD(SUMPRODUCT(--MID(SUBSTITUTE(SUBSTITUTE(SUBSTITUTE(SUBSTITUTE(E8,".",""),"-","")," ",""),"/",""),{1,2,3,4,5,6,7,8,9,10},1),{11,10,9,8,7,6,5,4,3,2}),11)<2,0,11-MOD(SUMPRODUCT(--MID(SUBSTITUTE(SUBSTITUTE(SUBSTITUTE(SUBSTITUTE(E8,".",""),"-","")," ",""),"/",""),{1,2,3,4,5,6,7,8,9,10},1),{11,10,9,8,7,6,5,4,3,2}),11))),FALSE()),AND(LEN(SUBSTITUTE(SUBSTITUTE(SUBSTITUTE(SUBSTITUTE(E8,".",""),"-","")," ",""),"/",""))=14,ISNUMBER(VALUE(SUBSTITUTE(SUBSTITUTE(SUBSTITUTE(SUBSTITUTE(E8,".",""),"-","")," ",""),"/",""))))),FALSE()))),"Revisar",IF(G8<>"Sim","Falta comprovante",IF(AND(B8="Educação",SUMIFS($F$6:$F$155,$B$6:$B$155,"Educação",$C$6:$C$155,C8)>Parâmetros!$B$6),"Acima do limite","OK")))) -> Acima do limite
A9: 46387 | B9: Previdência privada (PGBL) | C9: Fulano de Tal (exemplo) | D9: Previdência Exemplo | E9: 45.678.901/0001-23 | F9: 3000 | G9: Não | I9: =IF(AND(B9="",F9=""),"",IF(OR(A9="",B9="",C9="",F9="",NOT(IFERROR(OR(IFERROR(AND(LEN(SUBSTITUTE(SUBSTITUTE(SUBSTITUTE(SUBSTITUTE(E9,".",""),"-","")," ",""),"/",""))=11,SUBSTITUTE(SUBSTITUTE(SUBSTITUTE(SUBSTITUTE(E9,".",""),"-","")," ",""),"/","")<>REPT(LEFT(SUBSTITUTE(SUBSTITUTE(SUBSTITUTE(SUBSTITUTE(E9,".",""),"-","")," ",""),"/",""),1),11),VALUE(MID(SUBSTITUTE(SUBSTITUTE(SUBSTITUTE(SUBSTITUTE(E9,".",""),"-","")," ",""),"/",""),10,1))=IF(MOD(SUMPRODUCT(--MID(SUBSTITUTE(SUBSTITUTE(SUBSTITUTE(SUBSTITUTE(E9,".",""),"-","")," ",""),"/",""),{1,2,3,4,5,6,7,8,9},1),{10,9,8,7,6,5,4,3,2}),11)<2,0,11-MOD(SUMPRODUCT(--MID(SUBSTITUTE(SUBSTITUTE(SUBSTITUTE(SUBSTITUTE(E9,".",""),"-","")," ",""),"/",""),{1,2,3,4,5,6,7,8,9},1),{10,9,8,7,6,5,4,3,2}),11)),VALUE(MID(SUBSTITUTE(SUBSTITUTE(SUBSTITUTE(SUBSTITUTE(E9,".",""),"-","")," ",""),"/",""),11,1))=IF(MOD(SUMPRODUCT(--MID(SUBSTITUTE(SUBSTITUTE(SUBSTITUTE(SUBSTITUTE(E9,".",""),"-","")," ",""),"/",""),{1,2,3,4,5,6,7,8,9,10},1),{11,10,9,8,7,6,5,4,3,2}),11)<2,0,11-MOD(SUMPRODUCT(--MID(SUBSTITUTE(SUBSTITUTE(SUBSTITUTE(SUBSTITUTE(E9,".",""),"-","")," ",""),"/",""),{1,2,3,4,5,6,7,8,9,10},1),{11,10,9,8,7,6,5,4,3,2}),11))),FALSE()),AND(LEN(SUBSTITUTE(SUBSTITUTE(SUBSTITUTE(SUBSTITUTE(E9,".",""),"-","")," ",""),"/",""))=14,ISNUMBER(VALUE(SUBSTITUTE(SUBSTITUTE(SUBSTITUTE(SUBSTITUTE(E9,".",""),"-","")," ",""),"/",""))))),FALSE()))),"Revisar",IF(G9<>"Sim","Falta comprovante",IF(AND(B9="Educação",SUMIFS($F$6:$F$155,$B$6:$B$155,"Educação",$C$6:$C$155,C9)>Parâmetros!$B$6),"Acima do limite","OK")))) -> Falta comprovante
I10: =IF(AND(B10="",F10=""),"",IF(OR(A10="",B10="",C10="",F10="",NOT(IFERROR(OR(IFERROR(AND(LEN(SUBSTITUTE(SUBSTITUTE(SUBSTITUTE(SUBSTITUTE(E10,".",""),"-","")," ",""),"/",""))=11,SUBSTITUTE(SUBSTITUTE(SUBSTITUTE(SUBSTITUTE(E10,".",""),"-","")," ",""),"/","")<>REPT(LEFT(SUBSTITUTE(SUBSTITUTE(SUBSTITUTE(SUBSTITUTE(E10,".",""),"-","")," ",""),"/",""),1),11),VALUE(MID(SUBSTITUTE(SUBSTITUTE(SUBSTITUTE(SUBSTITUTE(E10,".",""),"-","")," ",""),"/",""),10,1))=IF(MOD(SUMPRODUCT(--MID(SUBSTITUTE(SUBSTITUTE(SUBSTITUTE(SUBSTITUTE(E10,".",""),"-","")," ",""),"/",""),{1,2,3,4,5,6,7,8,9},1),{10,9,8,7,6,5,4,3,2}),11)<2,0,11-MOD(SUMPRODUCT(--MID(SUBSTITUTE(SUBSTITUTE(SUBSTITUTE(SUBSTITUTE(E10,".",""),"-","")," ",""),"/",""),{1,2,3,4,5,6,7,8,9},1),{10,9,8,7,6,5,4,3,2}),11)),VALUE(MID(SUBSTITUTE(SUBSTITUTE(SUBSTITUTE(SUBSTITUTE(E10,".",""),"-","")," ",""),"/",""),11,1))=IF(MOD(SUMPRODUCT(--MID(SUBSTITUTE(SUBSTITUTE(SUBSTITUTE(SUBSTITUTE(E10,".",""),"-","")," ",""),"/",""),{1,2,3,4,5,6,7,8,9,10},1),{11,10,9,8,7,6,5,4,3,2}),11)<2,0,11-MOD(SUMPRODUCT(--MID(SUBSTITUTE(SUBSTITUTE(SUBSTITUTE(SUBSTITUTE(E10,".",""),"-","")," ",""),"/",""),{1,2,3,4,5,6,7,8,9,10},1),{11,10,9,8,7,6,5,4,3,2}),11))),FALSE()),AND(LEN(SUBSTITUTE(SUBSTITUTE(SUBSTITUTE(SUBSTITUTE(E10,".",""),"-","")," ",""),"/",""))=14,ISNUMBER(VALUE(SUBSTITUTE(SUBSTITUTE(SUBSTITUTE(SUBSTITUTE(E10,".",""),"-","")," ",""),"/",""))))),FALSE()))),"Revisar",IF(G10<>"Sim","Falta comprovante",IF(AND(B10="Educação",SUMIFS($F$6:$F$155,$B$6:$B$155,"Educação",$C$6:$C$155,C10)>Parâmetros!$B$6),"Acima do limite","OK"))))
I11: =IF(AND(B11="",F11=""),"",IF(OR(A11="",B11="",C11="",F11="",NOT(IFERROR(OR(IFERROR(AND(LEN(SUBSTITUTE(SUBSTITUTE(SUBSTITUTE(SUBSTITUTE(E11,".",""),"-","")," ",""),"/",""))=11,SUBSTITUTE(SUBSTITUTE(SUBSTITUTE(SUBSTITUTE(E11,".",""),"-","")," ",""),"/","")<>REPT(LEFT(SUBSTITUTE(SUBSTITUTE(SUBSTITUTE(SUBSTITUTE(E11,".",""),"-","")," ",""),"/",""),1),11),VALUE(MID(SUBSTITUTE(SUBSTITUTE(SUBSTITUTE(SUBSTITUTE(E11,".",""),"-","")," ",""),"/",""),10,1))=IF(MOD(SUMPRODUCT(--MID(SUBSTITUTE(SUBSTITUTE(SUBSTITUTE(SUBSTITUTE(E11,".",""),"-","")," ",""),"/",""),{1,2,3,4,5,6,7,8,9},1),{10,9,8,7,6,5,4,3,2}),11)<2,0,11-MOD(SUMPRODUCT(--MID(SUBSTITUTE(SUBSTITUTE(SUBSTITUTE(SUBSTITUTE(E11,".",""),"-","")," ",""),"/",""),{1,2,3,4,5,6,7,8,9},1),{10,9,8,7,6,5,4,3,2}),11)),VALUE(MID(SUBSTITUTE(SUBSTITUTE(SUBSTITUTE(SUBSTITUTE(E11,".",""),"-","")," ",""),"/",""),11,1))=IF(MOD(SUMPRODUCT(--MID(SUBSTITUTE(SUBSTITUTE(SUBSTITUTE(SUBSTITUTE(E11,".",""),"-","")," ",""),"/",""),{1,2,3,4,5,6,7,8,9,10},1),{11,10,9,8,7,6,5,4,3,2}),11)<2,0,11-MOD(SUMPRODUCT(--MID(SUBSTITUTE(SUBSTITUTE(SUBSTITUTE(SUBSTITUTE(E11,".",""),"-","")," ",""),"/",""),{1,2,3,4,5,6,7,8,9,10},1),{11,10,9,8,7,6,5,4,3,2}),11))),FALSE()),AND(LEN(SUBSTITUTE(SUBSTITUTE(SUBSTITUTE(SUBSTITUTE(E11,".",""),"-","")," ",""),"/",""))=14,ISNUMBER(VALUE(SUBSTITUTE(SUBSTITUTE(SUBSTITUTE(SUBSTITUTE(E11,".",""),"-","")," ",""),"/",""))))),FALSE()))),"Revisar",IF(G11<>"Sim","Falta comprovante",IF(AND(B11="Educação",SUMIFS($F$6:$F$155,$B$6:$B$155,"Educação",$C$6:$C$155,C11)>Parâmetros!$B$6),"Acima do limite","OK"))))
I12: =IF(AND(B12="",F12=""),"",IF(OR(A12="",B12="",C12="",F12="",NOT(IFERROR(OR(IFERROR(AND(LEN(SUBSTITUTE(SUBSTITUTE(SUBSTITUTE(SUBSTITUTE(E12,".",""),"-","")," ",""),"/",""))=11,SUBSTITUTE(SUBSTITUTE(SUBSTITUTE(SUBSTITUTE(E12,".",""),"-","")," ",""),"/","")<>REPT(LEFT(SUBSTITUTE(SUBSTITUTE(SUBSTITUTE(SUBSTITUTE(E12,".",""),"-","")," ",""),"/",""),1),11),VALUE(MID(SUBSTITUTE(SUBSTITUTE(SUBSTITUTE(SUBSTITUTE(E12,".",""),"-","")," ",""),"/",""),10,1))=IF(MOD(SUMPRODUCT(--MID(SUBSTITUTE(SUBSTITUTE(SUBSTITUTE(SUBSTITUTE(E12,".",""),"-","")," ",""),"/",""),{1,2,3,4,5,6,7,8,9},1),{10,9,8,7,6,5,4,3,2}),11)<2,0,11-MOD(SUMPRODUCT(--MID(SUBSTITUTE(SUBSTITUTE(SUBSTITUTE(SUBSTITUTE(E12,".",""),"-","")," ",""),"/",""),{1,2,3,4,5,6,7,8,9},1),{10,9,8,7,6,5,4,3,2}),11)),VALUE(MID(SUBSTITUTE(SUBSTITUTE(SUBSTITUTE(SUBSTITUTE(E12,".",""),"-","")," ",""),"/",""),11,1))=IF(MOD(SUMPRODUCT(--MID(SUBSTITUTE(SUBSTITUTE(SUBSTITUTE(SUBSTITUTE(E12,".",""),"-","")," ",""),"/",""),{1,2,3,4,5,6,7,8,9,10},1),{11,10,9,8,7,6,5,4,3,2}),11)<2,0,11-MOD(SUMPRODUCT(--MID(SUBSTITUTE(SUBSTITUTE(SUBSTITUTE(SUBSTITUTE(E12,".",""),"-","")," ",""),"/",""),{1,2,3,4,5,6,7,8,9,10},1),{11,10,9,8,7,6,5,4,3,2}),11))),FALSE()),AND(LEN(SUBSTITUTE(SUBSTITUTE(SUBSTITUTE(SUBSTITUTE(E12,".",""),"-","")," ",""),"/",""))=14,ISNUMBER(VALUE(SUBSTITUTE(SUBSTITUTE(SUBSTITUTE(SUBSTITUTE(E12,".",""),"-","")," ",""),"/",""))))),FALSE()))),"Revisar",IF(G12<>"Sim","Falta comprovante",IF(AND(B12="Educação",SUMIFS($F$6:$F$155,$B$6:$B$155,"Educação",$C$6:$C$155,C12)>Parâmetros!$B$6),"Acima do limite","OK"))))
I13: =IF(AND(B13="",F13=""),"",IF(OR(A13="",B13="",C13="",F13="",NOT(IFERROR(OR(IFERROR(AND(LEN(SUBSTITUTE(SUBSTITUTE(SUBSTITUTE(SUBSTITUTE(E13,".",""),"-","")," ",""),"/",""))=11,SUBSTITUTE(SUBSTITUTE(SUBSTITUTE(SUBSTITUTE(E13,".",""),"-","")," ",""),"/","")<>REPT(LEFT(SUBSTITUTE(SUBSTITUTE(SUBSTITUTE(SUBSTITUTE(E13,".",""),"-","")," ",""),"/",""),1),11),VALUE(MID(SUBSTITUTE(SUBSTITUTE(SUBSTITUTE(SUBSTITUTE(E13,".",""),"-","")," ",""),"/",""),10,1))=IF(MOD(SUMPRODUCT(--MID(SUBSTITUTE(SUBSTITUTE(SUBSTITUTE(SUBSTITUTE(E13,".",""),"-","")," ",""),"/",""),{1,2,3,4,5,6,7,8,9},1),{10,9,8,7,6,5,4,3,2}),11)<2,0,11-MOD(SUMPRODUCT(--MID(SUBSTITUTE(SUBSTITUTE(SUBSTITUTE(SUBSTITUTE(E13,".",""),"-","")," ",""),"/",""),{1,2,3,4,5,6,7,8,9},1),{10,9,8,7,6,5,4,3,2}),11)),VALUE(MID(SUBSTITUTE(SUBSTITUTE(SUBSTITUTE(SUBSTITUTE(E13,".",""),"-","")," ",""),"/",""),11,1))=IF(MOD(SUMPRODUCT(--MID(SUBSTITUTE(SUBSTITUTE(SUBSTITUTE(SUBSTITUTE(E13,".",""),"-","")," ",""),"/",""),{1,2,3,4,5,6,7,8,9,10},1),{11,10,9,8,7,6,5,4,3,2}),11)<2,0,11-MOD(SUMPRODUCT(--MID(SUBSTITUTE(SUBSTITUTE(SUBSTITUTE(SUBSTITUTE(E13,".",""),"-","")," ",""),"/",""),{1,2,3,4,5,6,7,8,9,10},1),{11,10,9,8,7,6,5,4,3,2}),11))),FALSE()),AND(LEN(SUBSTITUTE(SUBSTITUTE(SUBSTITUTE(SUBSTITUTE(E13,".",""),"-","")," ",""),"/",""))=14,ISNUMBER(VALUE(SUBSTITUTE(SUBSTITUTE(SUBSTITUTE(SUBSTITUTE(E13,".",""),"-","")," ",""),"/",""))))),FALSE()))),"Revisar",IF(G13<>"Sim","Falta comprovante",IF(AND(B13="Educação",SUMIFS($F$6:$F$155,$B$6:$B$155,"Educação",$C$6:$C$155,C13)>Parâmetros!$B$6),"Acima do limite","OK"))))
I14: =IF(AND(B14="",F14=""),"",IF(OR(A14="",B14="",C14="",F14="",NOT(IFERROR(OR(IFERROR(AND(LEN(SUBSTITUTE(SUBSTITUTE(SUBSTITUTE(SUBSTITUTE(E14,".",""),"-","")," ",""),"/",""))=11,SUBSTITUTE(SUBSTITUTE(SUBSTITUTE(SUBSTITUTE(E14,".",""),"-","")," ",""),"/","")<>REPT(LEFT(SUBSTITUTE(SUBSTITUTE(SUBSTITUTE(SUBSTITUTE(E14,".",""),"-","")," ",""),"/",""),1),11),VALUE(MID(SUBSTITUTE(SUBSTITUTE(SUBSTITUTE(SUBSTITUTE(E14,".",""),"-","")," ",""),"/",""),10,1))=IF(MOD(SUMPRODUCT(--MID(SUBSTITUTE(SUBSTITUTE(SUBSTITUTE(SUBSTITUTE(E14,".",""),"-","")," ",""),"/",""),{1,2,3,4,5,6,7,8,9},1),{10,9,8,7,6,5,4,3,2}),11)<2,0,11-MOD(SUMPRODUCT(--MID(SUBSTITUTE(SUBSTITUTE(SUBSTITUTE(SUBSTITUTE(E14,".",""),"-","")," ",""),"/",""),{1,2,3,4,5,6,7,8,9},1),{10,9,8,7,6,5,4,3,2}),11)),VALUE(MID(SUBSTITUTE(SUBSTITUTE(SUBSTITUTE(SUBSTITUTE(E14,".",""),"-","")," ",""),"/",""),11,1))=IF(MOD(SUMPRODUCT(--MID(SUBSTITUTE(SUBSTITUTE(SUBSTITUTE(SUBSTITUTE(E14,".",""),"-","")," ",""),"/",""),{1,2,3,4,5,6,7,8,9,10},1),{11,10,9,8,7,6,5,4,3,2}),11)<2,0,11-MOD(SUMPRODUCT(--MID(SUBSTITUTE(SUBSTITUTE(SUBSTITUTE(SUBSTITUTE(E14,".",""),"-","")," ",""),"/",""),{1,2,3,4,5,6,7,8,9,10},1),{11,10,9,8,7,6,5,4,3,2}),11))),FALSE()),AND(LEN(SUBSTITUTE(SUBSTITUTE(SUBSTITUTE(SUBSTITUTE(E14,".",""),"-","")," ",""),"/",""))=14,ISNUMBER(VALUE(SUBSTITUTE(SUBSTITUTE(SUBSTITUTE(SUBSTITUTE(E14,".",""),"-","")," ",""),"/",""))))),FALSE()))),"Revisar",IF(G14<>"Sim","Falta comprovante",IF(AND(B14="Educação",SUMIFS($F$6:$F$155,$B$6:$B$155,"Educação",$C$6:$C$155,C14)>Parâmetros!$B$6),"Acima do limite","OK"))))
I15: =IF(AND(B15="",F15=""),"",IF(OR(A15="",B15="",C15="",F15="",NOT(IFERROR(OR(IFERROR(AND(LEN(SUBSTITUTE(SUBSTITUTE(SUBSTITUTE(SUBSTITUTE(E15,".",""),"-","")," ",""),"/",""))=11,SUBSTITUTE(SUBSTITUTE(SUBSTITUTE(SUBSTITUTE(E15,".",""),"-","")," ",""),"/","")<>REPT(LEFT(SUBSTITUTE(SUBSTITUTE(SUBSTITUTE(SUBSTITUTE(E15,".",""),"-","")," ",""),"/",""),1),11),VALUE(MID(SUBSTITUTE(SUBSTITUTE(SUBSTITUTE(SUBSTITUTE(E15,".",""),"-","")," ",""),"/",""),10,1))=IF(MOD(SUMPRODUCT(--MID(SUBSTITUTE(SUBSTITUTE(SUBSTITUTE(SUBSTITUTE(E15,".",""),"-","")," ",""),"/",""),{1,2,3,4,5,6,7,8,9},1),{10,9,8,7,6,5,4,3,2}),11)<2,0,11-MOD(SUMPRODUCT(--MID(SUBSTITUTE(SUBSTITUTE(SUBSTITUTE(SUBSTITUTE(E15,".",""),"-","")," ",""),"/",""),{1,2,3,4,5,6,7,8,9},1),{10,9,8,7,6,5,4,3,2}),11)),VALUE(MID(SUBSTITUTE(SUBSTITUTE(SUBSTITUTE(SUBSTITUTE(E15,".",""),"-","")," ",""),"/",""),11,1))=IF(MOD(SUMPRODUCT(--MID(SUBSTITUTE(SUBSTITUTE(SUBSTITUTE(SUBSTITUTE(E15,".",""),"-","")," ",""),"/",""),{1,2,3,4,5,6,7,8,9,10},1),{11,10,9,8,7,6,5,4,3,2}),11)<2,0,11-MOD(SUMPRODUCT(--MID(SUBSTITUTE(SUBSTITUTE(SUBSTITUTE(SUBSTITUTE(E15,".",""),"-","")," ",""),"/",""),{1,2,3,4,5,6,7,8,9,10},1),{11,10,9,8,7,6,5,4,3,2}),11))),FALSE()),AND(LEN(SUBSTITUTE(SUBSTITUTE(SUBSTITUTE(SUBSTITUTE(E15,".",""),"-","")," ",""),"/",""))=14,ISNUMBER(VALUE(SUBSTITUTE(SUBSTITUTE(SUBSTITUTE(SUBSTITUTE(E15,".",""),"-","")," ",""),"/",""))))),FALSE()))),"Revisar",IF(G15<>"Sim","Falta comprovante",IF(AND(B15="Educação",SUMIFS($F$6:$F$155,$B$6:$B$155,"Educação",$C$6:$C$155,C15)>Parâmetros!$B$6),"Acima do limite","OK"))))
